/*
*** MADE BY MITHION'S .SCHEMATIC TO JAVA CONVERTING TOOL v1.6 ***
*/

package com.MixedCraft.gen;
import java.util.Random;

import net.minecraft.block.Block;
import net.minecraft.world.World;
import net.minecraft.world.gen.feature.WorldGenerator;

public class House1 extends WorldGenerator
{
	public House1() { }

	public boolean generate(World world, Random rand, int i, int j, int k) {
		world.setBlock(i + 0, j + 0, k + 0, Block.leaves.blockID);
		world.setBlock(i + 0, j + 0, k + 1, Block.leaves.blockID);
		world.setBlock(i + 0, j + 0, k + 2, Block.leaves.blockID);
		world.setBlock(i + 0, j + 0, k + 3, Block.leaves.blockID);
		world.setBlock(i + 0, j + 0, k + 4, Block.leaves.blockID);
		world.setBlock(i + 0, j + 0, k + 5, Block.leaves.blockID);
		world.setBlock(i + 0, j + 0, k + 6, Block.leaves.blockID);
		world.setBlock(i + 0, j + 0, k + 7, Block.leaves.blockID);
		world.setBlock(i + 0, j + 0, k + 8, Block.leaves.blockID);
		world.setBlock(i + 0, j + 0, k + 9, Block.leaves.blockID);
		world.setBlock(i + 0, j + 0, k + 10, Block.leaves.blockID);
		world.setBlock(i + 0, j + 0, k + 11, Block.leaves.blockID);
		world.setBlock(i + 0, j + 0, k + 12, Block.leaves.blockID);
		world.setBlock(i + 0, j + 1, k + 0, Block.leaves.blockID);
		world.setBlock(i + 0, j + 1, k + 1, Block.leaves.blockID);
		world.setBlock(i + 0, j + 1, k + 2, Block.leaves.blockID);
		world.setBlock(i + 0, j + 1, k + 3, Block.leaves.blockID);
		world.setBlock(i + 0, j + 1, k + 4, Block.leaves.blockID);
		world.setBlock(i + 0, j + 1, k + 5, Block.leaves.blockID);
		world.setBlock(i + 0, j + 1, k + 6, Block.leaves.blockID);
		world.setBlock(i + 0, j + 1, k + 7, Block.leaves.blockID);
		world.setBlock(i + 0, j + 1, k + 8, Block.leaves.blockID);
		world.setBlock(i + 0, j + 1, k + 9, Block.leaves.blockID);
		world.setBlock(i + 0, j + 1, k + 10, Block.leaves.blockID);
		world.setBlock(i + 0, j + 1, k + 11, Block.leaves.blockID);
		world.setBlock(i + 0, j + 1, k + 12, Block.leaves.blockID);
		world.setBlock(i + 0, j + 2, k + 0, Block.leaves.blockID);
		world.setBlock(i + 0, j + 2, k + 1, Block.leaves.blockID);
		world.setBlock(i + 0, j + 2, k + 2, Block.leaves.blockID);
		world.setBlock(i + 0, j + 2, k + 3, Block.leaves.blockID);
		world.setBlock(i + 0, j + 2, k + 4, Block.leaves.blockID);
		world.setBlock(i + 0, j + 2, k + 5, Block.leaves.blockID);
		world.setBlock(i + 0, j + 2, k + 6, Block.leaves.blockID);
		world.setBlock(i + 0, j + 2, k + 7, Block.leaves.blockID);
		world.setBlock(i + 0, j + 2, k + 8, Block.leaves.blockID);
		world.setBlock(i + 0, j + 2, k + 9, Block.leaves.blockID);
		world.setBlock(i + 0, j + 2, k + 10, Block.leaves.blockID);
		world.setBlock(i + 0, j + 2, k + 11, Block.leaves.blockID);
		world.setBlock(i + 0, j + 2, k + 12, Block.leaves.blockID);
		world.setBlock(i + 0, j + 3, k + 0, 0);
		world.setBlock(i + 0, j + 3, k + 1, 0);
		world.setBlock(i + 0, j + 3, k + 2, 0);
		world.setBlock(i + 0, j + 3, k + 3, 0);
		world.setBlock(i + 0, j + 3, k + 4, 0);
		world.setBlock(i + 0, j + 3, k + 5, 0);
		world.setBlock(i + 0, j + 3, k + 6, 0);
		world.setBlock(i + 0, j + 3, k + 7, 0);
		world.setBlock(i + 0, j + 3, k + 8, 0);
		world.setBlock(i + 0, j + 3, k + 9, 0);
		world.setBlock(i + 0, j + 3, k + 10, 0);
		world.setBlock(i + 0, j + 3, k + 11, 0);
		world.setBlock(i + 0, j + 3, k + 12, 0);
		world.setBlock(i + 0, j + 4, k + 0, 0);
		world.setBlock(i + 0, j + 4, k + 1, 0);
		world.setBlock(i + 0, j + 4, k + 2, 0);
		world.setBlock(i + 0, j + 4, k + 3, 0);
		world.setBlock(i + 0, j + 4, k + 4, 0);
		world.setBlock(i + 0, j + 4, k + 5, 0);
		world.setBlock(i + 0, j + 4, k + 6, 0);
		world.setBlock(i + 0, j + 4, k + 7, 0);
		world.setBlock(i + 0, j + 4, k + 8, 0);
		world.setBlock(i + 0, j + 4, k + 9, 0);
		world.setBlock(i + 0, j + 4, k + 10, 0);
		world.setBlock(i + 0, j + 4, k + 11, 0);
		world.setBlock(i + 0, j + 4, k + 12, 0);
		world.setBlock(i + 1, j + 0, k + 0, Block.leaves.blockID);
		world.setBlock(i + 1, j + 0, k + 1, 0);
		world.setBlock(i + 1, j + 0, k + 2, 0);
		world.setBlock(i + 1, j + 0, k + 3, 0);
		world.setBlock(i + 1, j + 0, k + 4, 0);
		world.setBlock(i + 1, j + 0, k + 5, 0);
		world.setBlock(i + 1, j + 0, k + 6, 0);
		world.setBlock(i + 1, j + 0, k + 7, 0);
		world.setBlock(i + 1, j + 0, k + 8, 0);
		world.setBlock(i + 1, j + 0, k + 9, 0);
		world.setBlock(i + 1, j + 0, k + 10, 0);
		world.setBlock(i + 1, j + 0, k + 11, 0);
		world.setBlock(i + 1, j + 0, k + 12, Block.leaves.blockID);
		world.setBlock(i + 1, j + 1, k + 0, Block.leaves.blockID);
		world.setBlock(i + 1, j + 1, k + 1, 0);
		world.setBlock(i + 1, j + 1, k + 2, 0);
		world.setBlock(i + 1, j + 1, k + 3, 0);
		world.setBlock(i + 1, j + 1, k + 4, 0);
		world.setBlock(i + 1, j + 1, k + 5, 0);
		world.setBlock(i + 1, j + 1, k + 6, 0);
		world.setBlock(i + 1, j + 1, k + 7, 0);
		world.setBlock(i + 1, j + 1, k + 8, 0);
		world.setBlock(i + 1, j + 1, k + 9, 0);
		world.setBlock(i + 1, j + 1, k + 10, 0);
		world.setBlock(i + 1, j + 1, k + 11, 0);
		world.setBlock(i + 1, j + 1, k + 12, Block.leaves.blockID);
		world.setBlock(i + 1, j + 2, k + 0, Block.leaves.blockID);
		world.setBlock(i + 1, j + 2, k + 1, 0);
		world.setBlock(i + 1, j + 2, k + 2, 0);
		world.setBlock(i + 1, j + 2, k + 3, 0);
		world.setBlock(i + 1, j + 2, k + 4, 0);
		world.setBlock(i + 1, j + 2, k + 5, 0);
		world.setBlock(i + 1, j + 2, k + 6, 0);
		world.setBlock(i + 1, j + 2, k + 7, 0);
		world.setBlock(i + 1, j + 2, k + 8, 0);
		world.setBlock(i + 1, j + 2, k + 9, 0);
		world.setBlock(i + 1, j + 2, k + 10, 0);
		world.setBlock(i + 1, j + 2, k + 11, 0);
		world.setBlock(i + 1, j + 2, k + 12, Block.leaves.blockID);
		world.setBlock(i + 1, j + 3, k + 0, 0);
		world.setBlock(i + 1, j + 3, k + 1, 0);
		world.setBlock(i + 1, j + 3, k + 2, 0);
		world.setBlock(i + 1, j + 3, k + 3, 0);
		world.setBlock(i + 1, j + 3, k + 4, 0);
		world.setBlock(i + 1, j + 3, k + 5, 0);
		world.setBlock(i + 1, j + 3, k + 6, 0);
		world.setBlock(i + 1, j + 3, k + 7, 0);
		world.setBlock(i + 1, j + 3, k + 8, 0);
		world.setBlock(i + 1, j + 3, k + 9, 0);
		world.setBlock(i + 1, j + 3, k + 10, 0);
		world.setBlock(i + 1, j + 3, k + 11, 0);
		world.setBlock(i + 1, j + 3, k + 12, 0);
		world.setBlock(i + 1, j + 4, k + 0, 0);
		world.setBlock(i + 1, j + 4, k + 1, 0);
		world.setBlock(i + 1, j + 4, k + 2, 0);
		world.setBlock(i + 1, j + 4, k + 3, 0);
		world.setBlock(i + 1, j + 4, k + 4, 0);
		world.setBlock(i + 1, j + 4, k + 5, 0);
		world.setBlock(i + 1, j + 4, k + 6, 0);
		world.setBlock(i + 1, j + 4, k + 7, 0);
		world.setBlock(i + 1, j + 4, k + 8, 0);
		world.setBlock(i + 1, j + 4, k + 9, 0);
		world.setBlock(i + 1, j + 4, k + 10, 0);
		world.setBlock(i + 1, j + 4, k + 11, 0);
		world.setBlock(i + 1, j + 4, k + 12, 0);
		world.setBlock(i + 2, j + 0, k + 0, Block.leaves.blockID);
		world.setBlock(i + 2, j + 0, k + 1, 0);
		world.setBlock(i + 2, j + 0, k + 2, 0);
		world.setBlock(i + 2, j + 0, k + 3, 0);
		world.setBlock(i + 2, j + 0, k + 4, 0);
		world.setBlock(i + 2, j + 0, k + 5, 0);
		world.setBlock(i + 2, j + 0, k + 6, 0);
		world.setBlock(i + 2, j + 0, k + 7, 0);
		world.setBlock(i + 2, j + 0, k + 8, 0);
		world.setBlock(i + 2, j + 0, k + 9, 0);
		world.setBlock(i + 2, j + 0, k + 10, 0);
		world.setBlock(i + 2, j + 0, k + 11, 0);
		world.setBlock(i + 2, j + 0, k + 12, Block.leaves.blockID);
		world.setBlock(i + 2, j + 1, k + 0, Block.leaves.blockID);
		world.setBlock(i + 2, j + 1, k + 1, 0);
		world.setBlock(i + 2, j + 1, k + 2, 0);
		world.setBlock(i + 2, j + 1, k + 3, 0);
		world.setBlock(i + 2, j + 1, k + 4, 0);
		world.setBlock(i + 2, j + 1, k + 5, 0);
		world.setBlock(i + 2, j + 1, k + 6, 0);
		world.setBlock(i + 2, j + 1, k + 7, 0);
		world.setBlock(i + 2, j + 1, k + 8, 0);
		world.setBlock(i + 2, j + 1, k + 9, 0);
		world.setBlock(i + 2, j + 1, k + 10, 0);
		world.setBlock(i + 2, j + 1, k + 11, 0);
		world.setBlock(i + 2, j + 1, k + 12, Block.leaves.blockID);
		world.setBlock(i + 2, j + 2, k + 0, Block.leaves.blockID);
		world.setBlock(i + 2, j + 2, k + 1, 0);
		world.setBlock(i + 2, j + 2, k + 2, 0);
		world.setBlock(i + 2, j + 2, k + 3, 0);
		world.setBlock(i + 2, j + 2, k + 4, 0);
		world.setBlock(i + 2, j + 2, k + 5, 0);
		world.setBlock(i + 2, j + 2, k + 6, 0);
		world.setBlock(i + 2, j + 2, k + 7, 0);
		world.setBlock(i + 2, j + 2, k + 8, 0);
		world.setBlock(i + 2, j + 2, k + 9, 0);
		world.setBlock(i + 2, j + 2, k + 10, 0);
		world.setBlock(i + 2, j + 2, k + 11, 0);
		world.setBlock(i + 2, j + 2, k + 12, Block.leaves.blockID);
		world.setBlock(i + 2, j + 3, k + 0, 0);
		world.setBlock(i + 2, j + 3, k + 1, 0);
		world.setBlock(i + 2, j + 3, k + 2, 0);
		world.setBlock(i + 2, j + 3, k + 3, 0);
		world.setBlock(i + 2, j + 3, k + 4, 0);
		world.setBlock(i + 2, j + 3, k + 5, 0);
		world.setBlock(i + 2, j + 3, k + 6, 0);
		world.setBlock(i + 2, j + 3, k + 7, 0);
		world.setBlock(i + 2, j + 3, k + 8, 0);
		world.setBlock(i + 2, j + 3, k + 9, 0);
		world.setBlock(i + 2, j + 3, k + 10, 0);
		world.setBlock(i + 2, j + 3, k + 11, 0);
		world.setBlock(i + 2, j + 3, k + 12, 0);
		world.setBlock(i + 2, j + 4, k + 0, 0);
		world.setBlock(i + 2, j + 4, k + 1, 0);
		world.setBlock(i + 2, j + 4, k + 2, 0);
		world.setBlock(i + 2, j + 4, k + 3, 0);
		world.setBlock(i + 2, j + 4, k + 4, 0);
		world.setBlock(i + 2, j + 4, k + 5, 0);
		world.setBlock(i + 2, j + 4, k + 6, 0);
		world.setBlock(i + 2, j + 4, k + 7, 0);
		world.setBlock(i + 2, j + 4, k + 8, 0);
		world.setBlock(i + 2, j + 4, k + 9, 0);
		world.setBlock(i + 2, j + 4, k + 10, 0);
		world.setBlock(i + 2, j + 4, k + 11, 0);
		world.setBlock(i + 2, j + 4, k + 12, 0);
		world.setBlock(i + 3, j + 0, k + 0, Block.leaves.blockID);
		world.setBlock(i + 3, j + 0, k + 1, 0);
		world.setBlock(i + 3, j + 0, k + 2, 0);
		world.setBlock(i + 3, j + 0, k + 3, Block.wood.blockID);
		world.setBlock(i + 3, j + 0, k + 4, Block.wood.blockID);
		world.setBlock(i + 3, j + 0, k + 5, Block.wood.blockID);
		world.setBlock(i + 3, j + 0, k + 6, Block.wood.blockID);
		world.setBlock(i + 3, j + 0, k + 7, Block.wood.blockID);
		world.setBlock(i + 3, j + 0, k + 8, Block.wood.blockID);
		world.setBlock(i + 3, j + 0, k + 9, Block.wood.blockID);
		world.setBlock(i + 3, j + 0, k + 10, 0);
		world.setBlock(i + 3, j + 0, k + 11, 0);
		world.setBlock(i + 3, j + 0, k + 12, Block.leaves.blockID);
		world.setBlock(i + 3, j + 1, k + 0, Block.leaves.blockID);
		world.setBlock(i + 3, j + 1, k + 1, 0);
		world.setBlock(i + 3, j + 1, k + 2, 0);
		world.setBlock(i + 3, j + 1, k + 3, 0);
		world.setBlock(i + 3, j + 1, k + 4, 0);
		world.setBlock(i + 3, j + 1, k + 5, 0);
		world.setBlock(i + 3, j + 1, k + 6, 0);
		world.setBlock(i + 3, j + 1, k + 7, 0);
		world.setBlock(i + 3, j + 1, k + 8, 0);
		world.setBlock(i + 3, j + 1, k + 9, 0);
		world.setBlock(i + 3, j + 1, k + 10, 0);
		world.setBlock(i + 3, j + 1, k + 11, 0);
		world.setBlock(i + 3, j + 1, k + 12, Block.leaves.blockID);
		world.setBlock(i + 3, j + 2, k + 0, Block.leaves.blockID);
		world.setBlock(i + 3, j + 2, k + 1, 0);
		world.setBlock(i + 3, j + 2, k + 2, 0);
		world.setBlock(i + 3, j + 2, k + 3, 0);
		world.setBlock(i + 3, j + 2, k + 4, 0);
		world.setBlock(i + 3, j + 2, k + 5, 0);
		world.setBlock(i + 3, j + 2, k + 6, 0);
		world.setBlock(i + 3, j + 2, k + 7, 0);
		world.setBlock(i + 3, j + 2, k + 8, 0);
		world.setBlock(i + 3, j + 2, k + 9, 0);
		world.setBlock(i + 3, j + 2, k + 10, 0);
		world.setBlock(i + 3, j + 2, k + 11, 0);
		world.setBlock(i + 3, j + 2, k + 12, Block.leaves.blockID);
		world.setBlock(i + 3, j + 3, k + 0, 0);
		world.setBlock(i + 3, j + 3, k + 1, 0);
		world.setBlock(i + 3, j + 3, k + 2, 0);
		world.setBlock(i + 3, j + 3, k + 3, 0);
		world.setBlock(i + 3, j + 3, k + 4, 0);
		world.setBlock(i + 3, j + 3, k + 5, 0);
		world.setBlock(i + 3, j + 3, k + 6, 0);
		world.setBlock(i + 3, j + 3, k + 7, 0);
		world.setBlock(i + 3, j + 3, k + 8, 0);
		world.setBlock(i + 3, j + 3, k + 9, 0);
		world.setBlock(i + 3, j + 3, k + 10, 0);
		world.setBlock(i + 3, j + 3, k + 11, 0);
		world.setBlock(i + 3, j + 3, k + 12, 0);
		world.setBlock(i + 3, j + 4, k + 0, 0);
		world.setBlock(i + 3, j + 4, k + 1, 0);
		world.setBlock(i + 3, j + 4, k + 2, 0);
		world.setBlock(i + 3, j + 4, k + 3, 0);
		world.setBlock(i + 3, j + 4, k + 4, 0);
		world.setBlock(i + 3, j + 4, k + 5, 0);
		world.setBlock(i + 3, j + 4, k + 6, 0);
		world.setBlock(i + 3, j + 4, k + 7, 0);
		world.setBlock(i + 3, j + 4, k + 8, 0);
		world.setBlock(i + 3, j + 4, k + 9, 0);
		world.setBlock(i + 3, j + 4, k + 10, 0);
		world.setBlock(i + 3, j + 4, k + 11, 0);
		world.setBlock(i + 3, j + 4, k + 12, 0);
		world.setBlock(i + 4, j + 0, k + 0, Block.leaves.blockID);
		world.setBlock(i + 4, j + 0, k + 1, 0);
		world.setBlock(i + 4, j + 0, k + 2, 0);
		world.setBlock(i + 4, j + 0, k + 3, Block.wood.blockID);
		world.setBlock(i + 4, j + 0, k + 4, Block.tilledField.blockID);
		world.setBlock(i + 4, j + 0, k + 5, Block.tilledField.blockID);
		world.setBlock(i + 4, j + 0, k + 6, Block.tilledField.blockID);
		world.setBlock(i + 4, j + 0, k + 7, Block.tilledField.blockID);
		world.setBlock(i + 4, j + 0, k + 8, Block.tilledField.blockID);
		world.setBlock(i + 4, j + 0, k + 9, Block.wood.blockID);
		world.setBlock(i + 4, j + 0, k + 10, 0);
		world.setBlock(i + 4, j + 0, k + 11, 0);
		world.setBlock(i + 4, j + 0, k + 12, Block.leaves.blockID);
		world.setBlock(i + 4, j + 1, k + 0, Block.leaves.blockID);
		world.setBlock(i + 4, j + 1, k + 1, 0);
		world.setBlock(i + 4, j + 1, k + 2, 0);
		world.setBlock(i + 4, j + 1, k + 3, 0);
		world.setBlock(i + 4, j + 1, k + 9, 0);
		world.setBlock(i + 4, j + 1, k + 10, 0);
		world.setBlock(i + 4, j + 1, k + 11, 0);
		world.setBlock(i + 4, j + 1, k + 12, Block.leaves.blockID);
		world.setBlock(i + 4, j + 2, k + 0, Block.leaves.blockID);
		world.setBlock(i + 4, j + 2, k + 1, 0);
		world.setBlock(i + 4, j + 2, k + 2, 0);
		world.setBlock(i + 4, j + 2, k + 3, 0);
		world.setBlock(i + 4, j + 2, k + 4, 0);
		world.setBlock(i + 4, j + 2, k + 5, 0);
		world.setBlock(i + 4, j + 2, k + 6, 0);
		world.setBlock(i + 4, j + 2, k + 7, 0);
		world.setBlock(i + 4, j + 2, k + 8, 0);
		world.setBlock(i + 4, j + 2, k + 9, 0);
		world.setBlock(i + 4, j + 2, k + 10, 0);
		world.setBlock(i + 4, j + 2, k + 11, 0);
		world.setBlock(i + 4, j + 2, k + 12, Block.leaves.blockID);
		world.setBlock(i + 4, j + 3, k + 0, 0);
		world.setBlock(i + 4, j + 3, k + 1, 0);
		world.setBlock(i + 4, j + 3, k + 2, 0);
		world.setBlock(i + 4, j + 3, k + 3, 0);
		world.setBlock(i + 4, j + 3, k + 4, 0);
		world.setBlock(i + 4, j + 3, k + 5, 0);
		world.setBlock(i + 4, j + 3, k + 6, 0);
		world.setBlock(i + 4, j + 3, k + 7, 0);
		world.setBlock(i + 4, j + 3, k + 8, 0);
		world.setBlock(i + 4, j + 3, k + 9, 0);
		world.setBlock(i + 4, j + 3, k + 10, 0);
		world.setBlock(i + 4, j + 3, k + 11, 0);
		world.setBlock(i + 4, j + 3, k + 12, 0);
		world.setBlock(i + 4, j + 4, k + 0, 0);
		world.setBlock(i + 4, j + 4, k + 1, 0);
		world.setBlock(i + 4, j + 4, k + 2, 0);
		world.setBlock(i + 4, j + 4, k + 3, 0);
		world.setBlock(i + 4, j + 4, k + 4, 0);
		world.setBlock(i + 4, j + 4, k + 5, 0);
		world.setBlock(i + 4, j + 4, k + 6, 0);
		world.setBlock(i + 4, j + 4, k + 7, 0);
		world.setBlock(i + 4, j + 4, k + 8, 0);
		world.setBlock(i + 4, j + 4, k + 9, 0);
		world.setBlock(i + 4, j + 4, k + 10, 0);
		world.setBlock(i + 4, j + 4, k + 11, 0);
		world.setBlock(i + 4, j + 4, k + 12, 0);
		world.setBlock(i + 5, j + 0, k + 0, Block.leaves.blockID);
		world.setBlock(i + 5, j + 0, k + 1, 0);
		world.setBlock(i + 5, j + 0, k + 2, 0);
		world.setBlock(i + 5, j + 0, k + 3, Block.wood.blockID);
		world.setBlock(i + 5, j + 0, k + 9, Block.wood.blockID);
		world.setBlock(i + 5, j + 0, k + 10, 0);
		world.setBlock(i + 5, j + 0, k + 11, 0);
		world.setBlock(i + 5, j + 0, k + 12, Block.leaves.blockID);
		world.setBlock(i + 5, j + 1, k + 0, Block.leaves.blockID);
		world.setBlock(i + 5, j + 1, k + 1, 0);
		world.setBlock(i + 5, j + 1, k + 2, 0);
		world.setBlock(i + 5, j + 1, k + 3, 0);
		world.setBlock(i + 5, j + 1, k + 4, 0);
		world.setBlock(i + 5, j + 1, k + 5, 0);
		world.setBlock(i + 5, j + 1, k + 6, 0);
		world.setBlock(i + 5, j + 1, k + 7, 0);
		world.setBlock(i + 5, j + 1, k + 8, 0);
		world.setBlock(i + 5, j + 1, k + 9, 0);
		world.setBlock(i + 5, j + 1, k + 10, 0);
		world.setBlock(i + 5, j + 1, k + 11, 0);
		world.setBlock(i + 5, j + 1, k + 12, Block.leaves.blockID);
		world.setBlock(i + 5, j + 2, k + 0, Block.leaves.blockID);
		world.setBlock(i + 5, j + 2, k + 1, 0);
		world.setBlock(i + 5, j + 2, k + 2, 0);
		world.setBlock(i + 5, j + 2, k + 3, 0);
		world.setBlock(i + 5, j + 2, k + 4, 0);
		world.setBlock(i + 5, j + 2, k + 5, 0);
		world.setBlock(i + 5, j + 2, k + 6, 0);
		world.setBlock(i + 5, j + 2, k + 7, 0);
		world.setBlock(i + 5, j + 2, k + 8, 0);
		world.setBlock(i + 5, j + 2, k + 9, 0);
		world.setBlock(i + 5, j + 2, k + 10, 0);
		world.setBlock(i + 5, j + 2, k + 11, 0);
		world.setBlock(i + 5, j + 2, k + 12, Block.leaves.blockID);
		world.setBlock(i + 5, j + 3, k + 0, 0);
		world.setBlock(i + 5, j + 3, k + 1, 0);
		world.setBlock(i + 5, j + 3, k + 2, 0);
		world.setBlock(i + 5, j + 3, k + 3, 0);
		world.setBlock(i + 5, j + 3, k + 4, Block.fence.blockID);
		world.setBlock(i + 5, j + 3, k + 5, Block.fence.blockID);
		world.setBlock(i + 5, j + 3, k + 6, Block.fence.blockID);
		world.setBlock(i + 5, j + 3, k + 7, Block.fence.blockID);
		world.setBlock(i + 5, j + 3, k + 8, Block.fence.blockID);
		world.setBlock(i + 5, j + 3, k + 9, 0);
		world.setBlock(i + 5, j + 3, k + 10, 0);
		world.setBlock(i + 5, j + 3, k + 11, 0);
		world.setBlock(i + 5, j + 3, k + 12, 0);
		world.setBlock(i + 5, j + 4, k + 0, 0);
		world.setBlock(i + 5, j + 4, k + 1, 0);
		world.setBlock(i + 5, j + 4, k + 2, 0);
		world.setBlock(i + 5, j + 4, k + 3, 0);
		world.setBlock(i + 5, j + 4, k + 4, Block.glowStone.blockID);
		world.setBlock(i + 5, j + 4, k + 5, Block.glowStone.blockID);
		world.setBlock(i + 5, j + 4, k + 6, Block.glowStone.blockID);
		world.setBlock(i + 5, j + 4, k + 7, Block.glowStone.blockID);
		world.setBlock(i + 5, j + 4, k + 8, Block.glowStone.blockID);
		world.setBlock(i + 5, j + 4, k + 9, 0);
		world.setBlock(i + 5, j + 4, k + 10, 0);
		world.setBlock(i + 5, j + 4, k + 11, 0);
		world.setBlock(i + 5, j + 4, k + 12, 0);
		world.setBlock(i + 6, j + 0, k + 0, Block.leaves.blockID);
		world.setBlock(i + 6, j + 0, k + 1, 0);
		world.setBlock(i + 6, j + 0, k + 2, 0);
		world.setBlock(i + 6, j + 0, k + 3, Block.wood.blockID);
		world.setBlock(i + 6, j + 0, k + 4, Block.tilledField.blockID);
		world.setBlock(i + 6, j + 0, k + 5, Block.tilledField.blockID);
		world.setBlock(i + 6, j + 0, k + 6, Block.tilledField.blockID);
		world.setBlock(i + 6, j + 0, k + 7, Block.tilledField.blockID);
		world.setBlock(i + 6, j + 0, k + 8, Block.tilledField.blockID);
		world.setBlock(i + 6, j + 0, k + 9, Block.wood.blockID);
		world.setBlock(i + 6, j + 0, k + 10, 0);
		world.setBlock(i + 6, j + 0, k + 11, 0);
		world.setBlock(i + 6, j + 0, k + 12, Block.leaves.blockID);
		world.setBlock(i + 6, j + 1, k + 0, Block.leaves.blockID);
		world.setBlock(i + 6, j + 1, k + 1, 0);
		world.setBlock(i + 6, j + 1, k + 2, 0);
		world.setBlock(i + 6, j + 1, k + 3, 0);
		world.setBlock(i + 6, j + 1, k + 9, 0);
		world.setBlock(i + 6, j + 1, k + 10, 0);
		world.setBlock(i + 6, j + 1, k + 11, 0);
		world.setBlock(i + 6, j + 1, k + 12, Block.leaves.blockID);
		world.setBlock(i + 6, j + 2, k + 0, Block.leaves.blockID);
		world.setBlock(i + 6, j + 2, k + 1, 0);
		world.setBlock(i + 6, j + 2, k + 2, 0);
		world.setBlock(i + 6, j + 2, k + 3, 0);
		world.setBlock(i + 6, j + 2, k + 4, 0);
		world.setBlock(i + 6, j + 2, k + 5, 0);
		world.setBlock(i + 6, j + 2, k + 6, 0);
		world.setBlock(i + 6, j + 2, k + 7, 0);
		world.setBlock(i + 6, j + 2, k + 8, 0);
		world.setBlock(i + 6, j + 2, k + 9, 0);
		world.setBlock(i + 6, j + 2, k + 10, 0);
		world.setBlock(i + 6, j + 2, k + 11, 0);
		world.setBlock(i + 6, j + 2, k + 12, Block.leaves.blockID);
		world.setBlock(i + 6, j + 3, k + 0, 0);
		world.setBlock(i + 6, j + 3, k + 1, 0);
		world.setBlock(i + 6, j + 3, k + 2, 0);
		world.setBlock(i + 6, j + 3, k + 3, 0);
		world.setBlock(i + 6, j + 3, k + 4, 0);
		world.setBlock(i + 6, j + 3, k + 5, 0);
		world.setBlock(i + 6, j + 3, k + 6, 0);
		world.setBlock(i + 6, j + 3, k + 7, 0);
		world.setBlock(i + 6, j + 3, k + 8, 0);
		world.setBlock(i + 6, j + 3, k + 9, 0);
		world.setBlock(i + 6, j + 3, k + 10, 0);
		world.setBlock(i + 6, j + 3, k + 11, 0);
		world.setBlock(i + 6, j + 3, k + 12, 0);
		world.setBlock(i + 6, j + 4, k + 0, 0);
		world.setBlock(i + 6, j + 4, k + 1, 0);
		world.setBlock(i + 6, j + 4, k + 2, 0);
		world.setBlock(i + 6, j + 4, k + 3, 0);
		world.setBlock(i + 6, j + 4, k + 4, 0);
		world.setBlock(i + 6, j + 4, k + 5, 0);
		world.setBlock(i + 6, j + 4, k + 6, 0);
		world.setBlock(i + 6, j + 4, k + 7, 0);
		world.setBlock(i + 6, j + 4, k + 8, 0);
		world.setBlock(i + 6, j + 4, k + 9, 0);
		world.setBlock(i + 6, j + 4, k + 10, 0);
		world.setBlock(i + 6, j + 4, k + 11, 0);
		world.setBlock(i + 6, j + 4, k + 12, 0);
		world.setBlock(i + 7, j + 0, k + 0, Block.leaves.blockID);
		world.setBlock(i + 7, j + 0, k + 1, 0);
		world.setBlock(i + 7, j + 0, k + 2, 0);
		world.setBlock(i + 7, j + 0, k + 3, Block.wood.blockID);
		world.setBlock(i + 7, j + 0, k + 4, Block.wood.blockID);
		world.setBlock(i + 7, j + 0, k + 5, Block.wood.blockID);
		world.setBlock(i + 7, j + 0, k + 6, Block.wood.blockID);
		world.setBlock(i + 7, j + 0, k + 7, Block.wood.blockID);
		world.setBlock(i + 7, j + 0, k + 8, Block.wood.blockID);
		world.setBlock(i + 7, j + 0, k + 9, Block.wood.blockID);
		world.setBlock(i + 7, j + 0, k + 10, 0);
		world.setBlock(i + 7, j + 0, k + 11, 0);
		world.setBlock(i + 7, j + 0, k + 12, Block.leaves.blockID);
		world.setBlock(i + 7, j + 1, k + 0, Block.leaves.blockID);
		world.setBlock(i + 7, j + 1, k + 1, 0);
		world.setBlock(i + 7, j + 1, k + 2, 0);
		world.setBlock(i + 7, j + 1, k + 3, 0);
		world.setBlock(i + 7, j + 1, k + 4, 0);
		world.setBlock(i + 7, j + 1, k + 5, 0);
		world.setBlock(i + 7, j + 1, k + 6, 0);
		world.setBlock(i + 7, j + 1, k + 7, 0);
		world.setBlock(i + 7, j + 1, k + 8, 0);
		world.setBlock(i + 7, j + 1, k + 9, 0);
		world.setBlock(i + 7, j + 1, k + 10, 0);
		world.setBlock(i + 7, j + 1, k + 11, 0);
		world.setBlock(i + 7, j + 1, k + 12, Block.leaves.blockID);
		world.setBlock(i + 7, j + 2, k + 0, Block.leaves.blockID);
		world.setBlock(i + 7, j + 2, k + 1, 0);
		world.setBlock(i + 7, j + 2, k + 2, 0);
		world.setBlock(i + 7, j + 2, k + 3, 0);
		world.setBlock(i + 7, j + 2, k + 4, 0);
		world.setBlock(i + 7, j + 2, k + 5, 0);
		world.setBlock(i + 7, j + 2, k + 6, 0);
		world.setBlock(i + 7, j + 2, k + 7, 0);
		world.setBlock(i + 7, j + 2, k + 8, 0);
		world.setBlock(i + 7, j + 2, k + 9, 0);
		world.setBlock(i + 7, j + 2, k + 10, 0);
		world.setBlock(i + 7, j + 2, k + 11, 0);
		world.setBlock(i + 7, j + 2, k + 12, Block.leaves.blockID);
		world.setBlock(i + 7, j + 3, k + 0, 0);
		world.setBlock(i + 7, j + 3, k + 1, 0);
		world.setBlock(i + 7, j + 3, k + 2, 0);
		world.setBlock(i + 7, j + 3, k + 3, 0);
		world.setBlock(i + 7, j + 3, k + 4, 0);
		world.setBlock(i + 7, j + 3, k + 5, 0);
		world.setBlock(i + 7, j + 3, k + 6, 0);
		world.setBlock(i + 7, j + 3, k + 7, 0);
		world.setBlock(i + 7, j + 3, k + 8, 0);
		world.setBlock(i + 7, j + 3, k + 9, 0);
		world.setBlock(i + 7, j + 3, k + 10, 0);
		world.setBlock(i + 7, j + 3, k + 11, 0);
		world.setBlock(i + 7, j + 3, k + 12, 0);
		world.setBlock(i + 7, j + 4, k + 0, 0);
		world.setBlock(i + 7, j + 4, k + 1, 0);
		world.setBlock(i + 7, j + 4, k + 2, 0);
		world.setBlock(i + 7, j + 4, k + 3, 0);
		world.setBlock(i + 7, j + 4, k + 4, 0);
		world.setBlock(i + 7, j + 4, k + 5, 0);
		world.setBlock(i + 7, j + 4, k + 6, 0);
		world.setBlock(i + 7, j + 4, k + 7, 0);
		world.setBlock(i + 7, j + 4, k + 8, 0);
		world.setBlock(i + 7, j + 4, k + 9, 0);
		world.setBlock(i + 7, j + 4, k + 10, 0);
		world.setBlock(i + 7, j + 4, k + 11, 0);
		world.setBlock(i + 7, j + 4, k + 12, 0);
		world.setBlock(i + 8, j + 0, k + 0, Block.leaves.blockID);
		world.setBlock(i + 8, j + 0, k + 1, 0);
		world.setBlock(i + 8, j + 0, k + 2, 0);
		world.setBlock(i + 8, j + 0, k + 3, 0);
		world.setBlock(i + 8, j + 0, k + 4, 0);
		world.setBlock(i + 8, j + 0, k + 5, 0);
		world.setBlock(i + 8, j + 0, k + 6, 0);
		world.setBlock(i + 8, j + 0, k + 7, 0);
		world.setBlock(i + 8, j + 0, k + 8, 0);
		world.setBlock(i + 8, j + 0, k + 9, 0);
		world.setBlock(i + 8, j + 0, k + 10, 0);
		world.setBlock(i + 8, j + 0, k + 11, 0);
		world.setBlock(i + 8, j + 0, k + 12, Block.leaves.blockID);
		world.setBlock(i + 8, j + 1, k + 0, Block.leaves.blockID);
		world.setBlock(i + 8, j + 1, k + 1, 0);
		world.setBlock(i + 8, j + 1, k + 2, 0);
		world.setBlock(i + 8, j + 1, k + 3, 0);
		world.setBlock(i + 8, j + 1, k + 4, 0);
		world.setBlock(i + 8, j + 1, k + 5, 0);
		world.setBlock(i + 8, j + 1, k + 6, 0);
		world.setBlock(i + 8, j + 1, k + 7, 0);
		world.setBlock(i + 8, j + 1, k + 8, 0);
		world.setBlock(i + 8, j + 1, k + 9, 0);
		world.setBlock(i + 8, j + 1, k + 10, 0);
		world.setBlock(i + 8, j + 1, k + 11, 0);
		world.setBlock(i + 8, j + 1, k + 12, Block.leaves.blockID);
		world.setBlock(i + 8, j + 2, k + 0, Block.leaves.blockID);
		world.setBlock(i + 8, j + 2, k + 1, 0);
		world.setBlock(i + 8, j + 2, k + 2, 0);
		world.setBlock(i + 8, j + 2, k + 3, 0);
		world.setBlock(i + 8, j + 2, k + 4, 0);
		world.setBlock(i + 8, j + 2, k + 5, 0);
		world.setBlock(i + 8, j + 2, k + 6, 0);
		world.setBlock(i + 8, j + 2, k + 7, 0);
		world.setBlock(i + 8, j + 2, k + 8, 0);
		world.setBlock(i + 8, j + 2, k + 9, 0);
		world.setBlock(i + 8, j + 2, k + 10, 0);
		world.setBlock(i + 8, j + 2, k + 11, 0);
		world.setBlock(i + 8, j + 2, k + 12, Block.leaves.blockID);
		world.setBlock(i + 8, j + 3, k + 0, 0);
		world.setBlock(i + 8, j + 3, k + 1, 0);
		world.setBlock(i + 8, j + 3, k + 2, 0);
		world.setBlock(i + 8, j + 3, k + 3, 0);
		world.setBlock(i + 8, j + 3, k + 4, 0);
		world.setBlock(i + 8, j + 3, k + 5, 0);
		world.setBlock(i + 8, j + 3, k + 6, 0);
		world.setBlock(i + 8, j + 3, k + 7, 0);
		world.setBlock(i + 8, j + 3, k + 8, 0);
		world.setBlock(i + 8, j + 3, k + 9, 0);
		world.setBlock(i + 8, j + 3, k + 10, 0);
		world.setBlock(i + 8, j + 3, k + 11, 0);
		world.setBlock(i + 8, j + 3, k + 12, 0);
		world.setBlock(i + 8, j + 4, k + 0, 0);
		world.setBlock(i + 8, j + 4, k + 1, 0);
		world.setBlock(i + 8, j + 4, k + 2, 0);
		world.setBlock(i + 8, j + 4, k + 3, 0);
		world.setBlock(i + 8, j + 4, k + 4, 0);
		world.setBlock(i + 8, j + 4, k + 5, 0);
		world.setBlock(i + 8, j + 4, k + 6, 0);
		world.setBlock(i + 8, j + 4, k + 7, 0);
		world.setBlock(i + 8, j + 4, k + 8, 0);
		world.setBlock(i + 8, j + 4, k + 9, 0);
		world.setBlock(i + 8, j + 4, k + 10, 0);
		world.setBlock(i + 8, j + 4, k + 11, 0);
		world.setBlock(i + 8, j + 4, k + 12, 0);
		world.setBlock(i + 9, j + 0, k + 0, Block.leaves.blockID);
		world.setBlock(i + 9, j + 0, k + 1, 0);
		world.setBlock(i + 9, j + 0, k + 2, 0);
		world.setBlock(i + 9, j + 0, k + 3, 0);
		world.setBlock(i + 9, j + 0, k + 4, 0);
		world.setBlock(i + 9, j + 0, k + 5, 0);
		world.setBlock(i + 9, j + 0, k + 6, 0);
		world.setBlock(i + 9, j + 0, k + 7, 0);
		world.setBlock(i + 9, j + 0, k + 8, 0);
		world.setBlock(i + 9, j + 0, k + 9, 0);
		world.setBlock(i + 9, j + 0, k + 10, 0);
		world.setBlock(i + 9, j + 0, k + 11, 0);
		world.setBlock(i + 9, j + 0, k + 12, Block.leaves.blockID);
		world.setBlock(i + 9, j + 1, k + 0, Block.leaves.blockID);
		world.setBlock(i + 9, j + 1, k + 1, 0);
		world.setBlock(i + 9, j + 1, k + 2, 0);
		world.setBlock(i + 9, j + 1, k + 3, 0);
		world.setBlock(i + 9, j + 1, k + 4, 0);
		world.setBlock(i + 9, j + 1, k + 5, 0);
		world.setBlock(i + 9, j + 1, k + 6, 0);
		world.setBlock(i + 9, j + 1, k + 7, 0);
		world.setBlock(i + 9, j + 1, k + 8, 0);
		world.setBlock(i + 9, j + 1, k + 9, 0);
		world.setBlock(i + 9, j + 1, k + 10, 0);
		world.setBlock(i + 9, j + 1, k + 11, 0);
		world.setBlock(i + 9, j + 1, k + 12, Block.leaves.blockID);
		world.setBlock(i + 9, j + 2, k + 0, Block.leaves.blockID);
		world.setBlock(i + 9, j + 2, k + 1, 0);
		world.setBlock(i + 9, j + 2, k + 2, 0);
		world.setBlock(i + 9, j + 2, k + 3, 0);
		world.setBlock(i + 9, j + 2, k + 4, 0);
		world.setBlock(i + 9, j + 2, k + 5, 0);
		world.setBlock(i + 9, j + 2, k + 6, 0);
		world.setBlock(i + 9, j + 2, k + 7, 0);
		world.setBlock(i + 9, j + 2, k + 8, 0);
		world.setBlock(i + 9, j + 2, k + 9, 0);
		world.setBlock(i + 9, j + 2, k + 10, 0);
		world.setBlock(i + 9, j + 2, k + 11, 0);
		world.setBlock(i + 9, j + 2, k + 12, Block.leaves.blockID);
		world.setBlock(i + 9, j + 3, k + 0, 0);
		world.setBlock(i + 9, j + 3, k + 1, 0);
		world.setBlock(i + 9, j + 3, k + 2, 0);
		world.setBlock(i + 9, j + 3, k + 3, 0);
		world.setBlock(i + 9, j + 3, k + 4, 0);
		world.setBlock(i + 9, j + 3, k + 5, 0);
		world.setBlock(i + 9, j + 3, k + 6, 0);
		world.setBlock(i + 9, j + 3, k + 7, 0);
		world.setBlock(i + 9, j + 3, k + 8, 0);
		world.setBlock(i + 9, j + 3, k + 9, 0);
		world.setBlock(i + 9, j + 3, k + 10, 0);
		world.setBlock(i + 9, j + 3, k + 11, 0);
		world.setBlock(i + 9, j + 3, k + 12, 0);
		world.setBlock(i + 9, j + 4, k + 0, 0);
		world.setBlock(i + 9, j + 4, k + 1, 0);
		world.setBlock(i + 9, j + 4, k + 2, 0);
		world.setBlock(i + 9, j + 4, k + 3, 0);
		world.setBlock(i + 9, j + 4, k + 4, 0);
		world.setBlock(i + 9, j + 4, k + 5, 0);
		world.setBlock(i + 9, j + 4, k + 6, 0);
		world.setBlock(i + 9, j + 4, k + 7, 0);
		world.setBlock(i + 9, j + 4, k + 8, 0);
		world.setBlock(i + 9, j + 4, k + 9, 0);
		world.setBlock(i + 9, j + 4, k + 10, 0);
		world.setBlock(i + 9, j + 4, k + 11, 0);
		world.setBlock(i + 9, j + 4, k + 12, 0);
		world.setBlock(i + 10, j + 0, k + 0, Block.leaves.blockID);
		world.setBlock(i + 10, j + 0, k + 1, 0);
		world.setBlock(i + 10, j + 0, k + 2, 0);
		world.setBlock(i + 10, j + 0, k + 3, Block.planks.blockID);
		world.setBlock(i + 10, j + 0, k + 4, Block.planks.blockID);
		world.setBlock(i + 10, j + 0, k + 5, Block.planks.blockID);
		world.setBlock(i + 10, j + 0, k + 6, Block.planks.blockID);
		world.setBlock(i + 10, j + 0, k + 7, Block.planks.blockID);
		world.setBlock(i + 10, j + 0, k + 8, Block.planks.blockID);
		world.setBlock(i + 10, j + 0, k + 9, Block.planks.blockID);
		world.setBlock(i + 10, j + 0, k + 10, 0);
		world.setBlock(i + 10, j + 0, k + 11, 0);
		world.setBlock(i + 10, j + 0, k + 12, Block.leaves.blockID);
		world.setBlock(i + 10, j + 1, k + 0, Block.leaves.blockID);
		world.setBlock(i + 10, j + 1, k + 1, 0);
		world.setBlock(i + 10, j + 1, k + 2, 0);
		world.setBlock(i + 10, j + 1, k + 3, Block.planks.blockID);
		world.setBlock(i + 10, j + 1, k + 4, Block.planks.blockID);
		world.setBlock(i + 10, j + 1, k + 5, Block.planks.blockID);
		world.setBlock(i + 10, j + 1, k + 6, Block.planks.blockID);
		world.setBlock(i + 10, j + 1, k + 7, Block.planks.blockID);
		world.setBlock(i + 10, j + 1, k + 8, Block.planks.blockID);
		world.setBlock(i + 10, j + 1, k + 9, Block.planks.blockID);
		world.setBlock(i + 10, j + 1, k + 10, 0);
		world.setBlock(i + 10, j + 1, k + 11, 0);
		world.setBlock(i + 10, j + 1, k + 12, Block.leaves.blockID);
		world.setBlock(i + 10, j + 2, k + 0, Block.leaves.blockID);
		world.setBlock(i + 10, j + 2, k + 1, 0);
		world.setBlock(i + 10, j + 2, k + 2, 0);
		world.setBlock(i + 10, j + 2, k + 3, Block.glass.blockID);
		world.setBlock(i + 10, j + 2, k + 4, Block.glass.blockID);
		world.setBlock(i + 10, j + 2, k + 5, Block.glass.blockID);
		world.setBlock(i + 10, j + 2, k + 6, Block.glass.blockID);
		world.setBlock(i + 10, j + 2, k + 7, Block.glass.blockID);
		world.setBlock(i + 10, j + 2, k + 8, Block.glass.blockID);
		world.setBlock(i + 10, j + 2, k + 9, Block.glass.blockID);
		world.setBlock(i + 10, j + 2, k + 10, 0);
		world.setBlock(i + 10, j + 2, k + 11, 0);
		world.setBlock(i + 10, j + 2, k + 12, Block.leaves.blockID);
		world.setBlock(i + 10, j + 3, k + 0, 0);
		world.setBlock(i + 10, j + 3, k + 1, 0);
		world.setBlock(i + 10, j + 3, k + 2, 0);
		world.setBlock(i + 10, j + 3, k + 3, Block.planks.blockID);
		world.setBlock(i + 10, j + 3, k + 4, Block.planks.blockID);
		world.setBlock(i + 10, j + 3, k + 5, Block.planks.blockID);
		world.setBlock(i + 10, j + 3, k + 6, Block.planks.blockID);
		world.setBlock(i + 10, j + 3, k + 7, Block.planks.blockID);
		world.setBlock(i + 10, j + 3, k + 8, Block.planks.blockID);
		world.setBlock(i + 10, j + 3, k + 9, Block.planks.blockID);
		world.setBlock(i + 10, j + 3, k + 10, 0);
		world.setBlock(i + 10, j + 3, k + 11, 0);
		world.setBlock(i + 10, j + 3, k + 12, 0);
		world.setBlock(i + 10, j + 4, k + 0, 0);
		world.setBlock(i + 10, j + 4, k + 1, 0);
		world.setBlock(i + 10, j + 4, k + 2, 0);
		world.setBlock(i + 10, j + 4, k + 3, 0);
		world.setBlock(i + 10, j + 4, k + 4, 0);
		world.setBlock(i + 10, j + 4, k + 5, 0);
		world.setBlock(i + 10, j + 4, k + 6, 0);
		world.setBlock(i + 10, j + 4, k + 7, 0);
		world.setBlock(i + 10, j + 4, k + 8, 0);
		world.setBlock(i + 10, j + 4, k + 9, 0);
		world.setBlock(i + 10, j + 4, k + 10, 0);
		world.setBlock(i + 10, j + 4, k + 11, 0);
		world.setBlock(i + 10, j + 4, k + 12, 0);
		world.setBlock(i + 11, j + 0, k + 0, Block.leaves.blockID);
		world.setBlock(i + 11, j + 0, k + 1, 0);
		world.setBlock(i + 11, j + 0, k + 2, 0);
		world.setBlock(i + 11, j + 0, k + 3, Block.planks.blockID);
		world.setBlock(i + 11, j + 0, k + 4, Block.planks.blockID);
		world.setBlock(i + 11, j + 0, k + 5, Block.planks.blockID);
		world.setBlock(i + 11, j + 0, k + 6, Block.cloth.blockID);
		world.setBlock(i + 11, j + 0, k + 7, Block.planks.blockID);
		world.setBlock(i + 11, j + 0, k + 8, Block.planks.blockID);
		world.setBlock(i + 11, j + 0, k + 9, Block.planks.blockID);
		world.setBlock(i + 11, j + 0, k + 10, 0);
		world.setBlock(i + 11, j + 0, k + 11, 0);
		world.setBlock(i + 11, j + 0, k + 12, Block.leaves.blockID);
		world.setBlock(i + 11, j + 1, k + 0, Block.leaves.blockID);
		world.setBlock(i + 11, j + 1, k + 1, 0);
		world.setBlock(i + 11, j + 1, k + 2, 0);
		world.setBlock(i + 11, j + 1, k + 3, Block.planks.blockID);
		world.setBlock(i + 11, j + 1, k + 4, Block.chest.blockID);
		world.setBlock(i + 11, j + 1, k + 5, Block.chest.blockID);
		world.setBlock(i + 11, j + 1, k + 6, Block.bed.blockID, 0, 0);
		world.setBlock(i + 11, j + 1, k + 7, Block.chest.blockID);
		world.setBlock(i + 11, j + 1, k + 8, Block.chest.blockID);
		world.setBlock(i + 11, j + 1, k + 9, Block.planks.blockID);
		world.setBlock(i + 11, j + 1, k + 10, 0);
		world.setBlock(i + 11, j + 1, k + 11, 0);
		world.setBlock(i + 11, j + 1, k + 12, Block.leaves.blockID);
		world.setBlock(i + 11, j + 2, k + 0, Block.leaves.blockID);
		world.setBlock(i + 11, j + 2, k + 1, 0);
		world.setBlock(i + 11, j + 2, k + 2, 0);
		world.setBlock(i + 11, j + 2, k + 3, Block.glass.blockID);
		world.setBlock(i + 11, j + 2, k + 4, 0);
		world.setBlock(i + 11, j + 2, k + 5, 0);
		world.setBlock(i + 11, j + 2, k + 6, 0);
		world.setBlock(i + 11, j + 2, k + 7, 0);
		world.setBlock(i + 11, j + 2, k + 8, 0);
		world.setBlock(i + 11, j + 2, k + 9, Block.glass.blockID);
		world.setBlock(i + 11, j + 2, k + 10, 0);
		world.setBlock(i + 11, j + 2, k + 11, 0);
		world.setBlock(i + 11, j + 2, k + 12, Block.leaves.blockID);
		world.setBlock(i + 11, j + 3, k + 0, 0);
		world.setBlock(i + 11, j + 3, k + 1, 0);
		world.setBlock(i + 11, j + 3, k + 2, 0);
		world.setBlock(i + 11, j + 3, k + 3, Block.planks.blockID);
		world.setBlock(i + 11, j + 3, k + 4, 0);
		world.setBlock(i + 11, j + 3, k + 5, 0);
		world.setBlock(i + 11, j + 3, k + 6, 0);
		world.setBlock(i + 11, j + 3, k + 7, 0);
		world.setBlock(i + 11, j + 3, k + 8, 0);
		world.setBlock(i + 11, j + 3, k + 9, Block.planks.blockID);
		world.setBlock(i + 11, j + 3, k + 10, 0);
		world.setBlock(i + 11, j + 3, k + 11, 0);
		world.setBlock(i + 11, j + 3, k + 12, 0);
		world.setBlock(i + 11, j + 4, k + 0, 0);
		world.setBlock(i + 11, j + 4, k + 1, 0);
		world.setBlock(i + 11, j + 4, k + 2, 0);
		world.setBlock(i + 11, j + 4, k + 3, 0);
		world.setBlock(i + 11, j + 4, k + 4, Block.planks.blockID);
		world.setBlock(i + 11, j + 4, k + 5, Block.planks.blockID);
		world.setBlock(i + 11, j + 4, k + 6, Block.planks.blockID);
		world.setBlock(i + 11, j + 4, k + 7, Block.planks.blockID);
		world.setBlock(i + 11, j + 4, k + 8, Block.planks.blockID);
		world.setBlock(i + 11, j + 4, k + 9, 0);
		world.setBlock(i + 11, j + 4, k + 10, 0);
		world.setBlock(i + 11, j + 4, k + 11, 0);
		world.setBlock(i + 11, j + 4, k + 12, 0);
		world.setBlock(i + 12, j + 0, k + 0, Block.leaves.blockID);
		world.setBlock(i + 12, j + 0, k + 1, 0);
		world.setBlock(i + 12, j + 0, k + 2, 0);
		world.setBlock(i + 12, j + 0, k + 3, Block.planks.blockID);
		world.setBlock(i + 12, j + 0, k + 4, Block.planks.blockID);
		world.setBlock(i + 12, j + 0, k + 5, Block.cloth.blockID);
		world.setBlock(i + 12, j + 0, k + 6, Block.cloth.blockID);
		world.setBlock(i + 12, j + 0, k + 7, Block.cloth.blockID);
		world.setBlock(i + 12, j + 0, k + 8, Block.planks.blockID);
		world.setBlock(i + 12, j + 0, k + 9, Block.planks.blockID);
		world.setBlock(i + 12, j + 0, k + 10, 0);
		world.setBlock(i + 12, j + 0, k + 11, 0);
		world.setBlock(i + 12, j + 0, k + 12, Block.leaves.blockID);
		world.setBlock(i + 12, j + 1, k + 0, Block.leaves.blockID);
		world.setBlock(i + 12, j + 1, k + 1, 0);
		world.setBlock(i + 12, j + 1, k + 2, 0);
		world.setBlock(i + 12, j + 1, k + 3, Block.planks.blockID);
		world.setBlock(i + 12, j + 1, k + 4, 0);
		world.setBlock(i + 12, j + 1, k + 5, 0);
		world.setBlock(i + 12, j + 1, k + 6, Block.bed.blockID);
		world.setBlock(i + 12, j + 1, k + 7, 0);
		world.setBlock(i + 12, j + 1, k + 8, 0);
		world.setBlock(i + 12, j + 1, k + 9, Block.planks.blockID);
		world.setBlock(i + 12, j + 1, k + 10, 0);
		world.setBlock(i + 12, j + 1, k + 11, 0);
		world.setBlock(i + 12, j + 1, k + 12, Block.leaves.blockID);
		world.setBlock(i + 12, j + 2, k + 0, Block.leaves.blockID);
		world.setBlock(i + 12, j + 2, k + 1, 0);
		world.setBlock(i + 12, j + 2, k + 2, 0);
		world.setBlock(i + 12, j + 2, k + 3, Block.glass.blockID);
		world.setBlock(i + 12, j + 2, k + 4, 0);
		world.setBlock(i + 12, j + 2, k + 5, 0);
		world.setBlock(i + 12, j + 2, k + 6, 0);
		world.setBlock(i + 12, j + 2, k + 7, 0);
		world.setBlock(i + 12, j + 2, k + 8, 0);
		world.setBlock(i + 12, j + 2, k + 9, Block.glass.blockID);
		world.setBlock(i + 12, j + 2, k + 10, 0);
		world.setBlock(i + 12, j + 2, k + 11, 0);
		world.setBlock(i + 12, j + 2, k + 12, Block.leaves.blockID);
		world.setBlock(i + 12, j + 3, k + 0, 0);
		world.setBlock(i + 12, j + 3, k + 1, 0);
		world.setBlock(i + 12, j + 3, k + 2, 0);
		world.setBlock(i + 12, j + 3, k + 3, Block.planks.blockID);
		world.setBlock(i + 12, j + 3, k + 4, 0);
		world.setBlock(i + 12, j + 3, k + 5, 0);
		world.setBlock(i + 12, j + 3, k + 6, 0);
		world.setBlock(i + 12, j + 3, k + 7, 0);
		world.setBlock(i + 12, j + 3, k + 8, 0);
		world.setBlock(i + 12, j + 3, k + 9, Block.planks.blockID);
		world.setBlock(i + 12, j + 3, k + 10, 0);
		world.setBlock(i + 12, j + 3, k + 11, 0);
		world.setBlock(i + 12, j + 3, k + 12, 0);
		world.setBlock(i + 12, j + 4, k + 0, 0);
		world.setBlock(i + 12, j + 4, k + 1, 0);
		world.setBlock(i + 12, j + 4, k + 2, 0);
		world.setBlock(i + 12, j + 4, k + 3, 0);
		world.setBlock(i + 12, j + 4, k + 4, Block.planks.blockID);
		world.setBlock(i + 12, j + 4, k + 5, Block.glass.blockID);
		world.setBlock(i + 12, j + 4, k + 6, Block.glass.blockID);
		world.setBlock(i + 12, j + 4, k + 7, Block.glass.blockID);
		world.setBlock(i + 12, j + 4, k + 8, Block.planks.blockID);
		world.setBlock(i + 12, j + 4, k + 9, 0);
		world.setBlock(i + 12, j + 4, k + 10, 0);
		world.setBlock(i + 12, j + 4, k + 11, 0);
		world.setBlock(i + 12, j + 4, k + 12, 0);
		world.setBlock(i + 13, j + 0, k + 0, Block.leaves.blockID);
		world.setBlock(i + 13, j + 0, k + 1, 0);
		world.setBlock(i + 13, j + 0, k + 2, 0);
		world.setBlock(i + 13, j + 0, k + 3, Block.planks.blockID);
		world.setBlock(i + 13, j + 0, k + 4, Block.cloth.blockID);
		world.setBlock(i + 13, j + 0, k + 5, Block.cloth.blockID);
		world.setBlock(i + 13, j + 0, k + 6, Block.glowStone.blockID);
		world.setBlock(i + 13, j + 0, k + 7, Block.cloth.blockID);
		world.setBlock(i + 13, j + 0, k + 8, Block.cloth.blockID);
		world.setBlock(i + 13, j + 0, k + 9, Block.planks.blockID);
		world.setBlock(i + 13, j + 0, k + 10, 0);
		world.setBlock(i + 13, j + 0, k + 11, 0);
		world.setBlock(i + 13, j + 0, k + 12, Block.leaves.blockID);
		world.setBlock(i + 13, j + 1, k + 0, Block.leaves.blockID);
		world.setBlock(i + 13, j + 1, k + 1, 0);
		world.setBlock(i + 13, j + 1, k + 2, 0);
		world.setBlock(i + 13, j + 1, k + 3, Block.planks.blockID);
		world.setBlock(i + 13, j + 1, k + 4, 0);
		world.setBlock(i + 13, j + 1, k + 5, 0);
		world.setBlock(i + 13, j + 1, k + 6, 0);
		world.setBlock(i + 13, j + 1, k + 7, 0);
		world.setBlock(i + 13, j + 1, k + 8, 0);
		world.setBlock(i + 13, j + 1, k + 9, Block.planks.blockID);
		world.setBlock(i + 13, j + 1, k + 10, 0);
		world.setBlock(i + 13, j + 1, k + 11, 0);
		world.setBlock(i + 13, j + 1, k + 12, Block.leaves.blockID);
		world.setBlock(i + 13, j + 2, k + 0, Block.leaves.blockID);
		world.setBlock(i + 13, j + 2, k + 1, 0);
		world.setBlock(i + 13, j + 2, k + 2, 0);
		world.setBlock(i + 13, j + 2, k + 3, Block.glass.blockID);
		world.setBlock(i + 13, j + 2, k + 4, 0);
		world.setBlock(i + 13, j + 2, k + 5, 0);
		world.setBlock(i + 13, j + 2, k + 6, 0);
		world.setBlock(i + 13, j + 2, k + 7, 0);
		world.setBlock(i + 13, j + 2, k + 8, 0);
		world.setBlock(i + 13, j + 2, k + 9, Block.glass.blockID);
		world.setBlock(i + 13, j + 2, k + 10, 0);
		world.setBlock(i + 13, j + 2, k + 11, 0);
		world.setBlock(i + 13, j + 2, k + 12, Block.leaves.blockID);
		world.setBlock(i + 13, j + 3, k + 0, 0);
		world.setBlock(i + 13, j + 3, k + 1, 0);
		world.setBlock(i + 13, j + 3, k + 2, 0);
		world.setBlock(i + 13, j + 3, k + 3, Block.planks.blockID);
		world.setBlock(i + 13, j + 3, k + 4, 0);
		world.setBlock(i + 13, j + 3, k + 5, 0);
		world.setBlock(i + 13, j + 3, k + 6, 0);
		world.setBlock(i + 13, j + 3, k + 7, 0);
		world.setBlock(i + 13, j + 3, k + 8, 0);
		world.setBlock(i + 13, j + 3, k + 9, Block.planks.blockID);
		world.setBlock(i + 13, j + 3, k + 10, 0);
		world.setBlock(i + 13, j + 3, k + 11, 0);
		world.setBlock(i + 13, j + 3, k + 12, 0);
		world.setBlock(i + 13, j + 4, k + 0, 0);
		world.setBlock(i + 13, j + 4, k + 1, 0);
		world.setBlock(i + 13, j + 4, k + 2, 0);
		world.setBlock(i + 13, j + 4, k + 3, 0);
		world.setBlock(i + 13, j + 4, k + 4, Block.planks.blockID);
		world.setBlock(i + 13, j + 4, k + 5, Block.glass.blockID);
		world.setBlock(i + 13, j + 4, k + 6, Block.blockDiamond.blockID);
		world.setBlock(i + 13, j + 4, k + 7, Block.glass.blockID);
		world.setBlock(i + 13, j + 4, k + 8, Block.planks.blockID);
		world.setBlock(i + 13, j + 4, k + 9, 0);
		world.setBlock(i + 13, j + 4, k + 10, 0);
		world.setBlock(i + 13, j + 4, k + 11, 0);
		world.setBlock(i + 13, j + 4, k + 12, 0);
		world.setBlock(i + 14, j + 0, k + 0, Block.leaves.blockID);
		world.setBlock(i + 14, j + 0, k + 1, 0);
		world.setBlock(i + 14, j + 0, k + 2, 0);
		world.setBlock(i + 14, j + 0, k + 3, Block.planks.blockID);
		world.setBlock(i + 14, j + 0, k + 4, Block.planks.blockID);
		world.setBlock(i + 14, j + 0, k + 5, Block.cloth.blockID);
		world.setBlock(i + 14, j + 0, k + 6, Block.cloth.blockID);
		world.setBlock(i + 14, j + 0, k + 7, Block.cloth.blockID);
		world.setBlock(i + 14, j + 0, k + 8, Block.planks.blockID);
		world.setBlock(i + 14, j + 0, k + 9, Block.planks.blockID);
		world.setBlock(i + 14, j + 0, k + 10, 0);
		world.setBlock(i + 14, j + 0, k + 11, 0);
		world.setBlock(i + 14, j + 0, k + 12, Block.leaves.blockID);
		world.setBlock(i + 14, j + 1, k + 0, Block.leaves.blockID);
		world.setBlock(i + 14, j + 1, k + 1, 0);
		world.setBlock(i + 14, j + 1, k + 2, 0);
		world.setBlock(i + 14, j + 1, k + 3, Block.planks.blockID);
		world.setBlock(i + 14, j + 1, k + 4, Block.woodSingleSlab.blockID);
		world.setBlock(i + 14, j + 1, k + 5, Block.fence.blockID);
		world.setBlock(i + 14, j + 1, k + 6, 0);
		world.setBlock(i + 14, j + 1, k + 7, 0);
		world.setBlock(i + 14, j + 1, k + 8, Block.furnaceIdle.blockID);
		world.setBlock(i + 14, j + 1, k + 9, Block.planks.blockID);
		world.setBlock(i + 14, j + 1, k + 10, 0);
		world.setBlock(i + 14, j + 1, k + 11, 0);
		world.setBlock(i + 14, j + 1, k + 12, Block.leaves.blockID);
		world.setBlock(i + 14, j + 2, k + 0, Block.leaves.blockID);
		world.setBlock(i + 14, j + 2, k + 1, 0);
		world.setBlock(i + 14, j + 2, k + 2, 0);
		world.setBlock(i + 14, j + 2, k + 3, Block.glass.blockID);
		world.setBlock(i + 14, j + 2, k + 4, 0);
		world.setBlock(i + 14, j + 2, k + 6, 0);
		world.setBlock(i + 14, j + 2, k + 7, 0);
		world.setBlock(i + 14, j + 2, k + 8, 0);
		world.setBlock(i + 14, j + 2, k + 9, Block.glass.blockID);
		world.setBlock(i + 14, j + 2, k + 10, 0);
		world.setBlock(i + 14, j + 2, k + 11, 0);
		world.setBlock(i + 14, j + 2, k + 12, Block.leaves.blockID);
		world.setBlock(i + 14, j + 3, k + 0, 0);
		world.setBlock(i + 14, j + 3, k + 1, 0);
		world.setBlock(i + 14, j + 3, k + 2, 0);
		world.setBlock(i + 14, j + 3, k + 3, Block.planks.blockID);
		world.setBlock(i + 14, j + 3, k + 4, 0);
		world.setBlock(i + 14, j + 3, k + 5, 0);
		world.setBlock(i + 14, j + 3, k + 6, 0);
		world.setBlock(i + 14, j + 3, k + 7, 0);
		world.setBlock(i + 14, j + 3, k + 8, 0);
		world.setBlock(i + 14, j + 3, k + 9, Block.planks.blockID);
		world.setBlock(i + 14, j + 3, k + 10, 0);
		world.setBlock(i + 14, j + 3, k + 11, 0);
		world.setBlock(i + 14, j + 3, k + 12, 0);
		world.setBlock(i + 14, j + 4, k + 0, 0);
		world.setBlock(i + 14, j + 4, k + 1, 0);
		world.setBlock(i + 14, j + 4, k + 2, 0);
		world.setBlock(i + 14, j + 4, k + 3, 0);
		world.setBlock(i + 14, j + 4, k + 4, Block.planks.blockID);
		world.setBlock(i + 14, j + 4, k + 5, Block.glass.blockID);
		world.setBlock(i + 14, j + 4, k + 6, Block.glass.blockID);
		world.setBlock(i + 14, j + 4, k + 7, Block.glass.blockID);
		world.setBlock(i + 14, j + 4, k + 8, Block.planks.blockID);
		world.setBlock(i + 14, j + 4, k + 9, 0);
		world.setBlock(i + 14, j + 4, k + 10, 0);
		world.setBlock(i + 14, j + 4, k + 11, 0);
		world.setBlock(i + 14, j + 4, k + 12, 0);
		world.setBlock(i + 15, j + 0, k + 0, Block.leaves.blockID);
		world.setBlock(i + 15, j + 0, k + 1, 0);
		world.setBlock(i + 15, j + 0, k + 2, 0);
		world.setBlock(i + 15, j + 0, k + 3, Block.planks.blockID);
		world.setBlock(i + 15, j + 0, k + 4, Block.planks.blockID);
		world.setBlock(i + 15, j + 0, k + 5, Block.planks.blockID);
		world.setBlock(i + 15, j + 0, k + 6, Block.cloth.blockID);
		world.setBlock(i + 15, j + 0, k + 7, Block.planks.blockID);
		world.setBlock(i + 15, j + 0, k + 8, Block.planks.blockID);
		world.setBlock(i + 15, j + 0, k + 9, Block.planks.blockID);
		world.setBlock(i + 15, j + 0, k + 10, 0);
		world.setBlock(i + 15, j + 0, k + 11, 0);
		world.setBlock(i + 15, j + 0, k + 12, Block.leaves.blockID);
		world.setBlock(i + 15, j + 1, k + 0, Block.leaves.blockID);
		world.setBlock(i + 15, j + 1, k + 1, 0);
		world.setBlock(i + 15, j + 1, k + 2, 0);
		world.setBlock(i + 15, j + 1, k + 3, Block.planks.blockID);
		world.setBlock(i + 15, j + 1, k + 4, Block.woodSingleSlab.blockID);
		world.setBlock(i + 15, j + 1, k + 5, Block.woodSingleSlab.blockID);
		world.setBlock(i + 15, j + 1, k + 6, 0);
		world.setBlock(i + 15, j + 1, k + 7, Block.furnaceIdle.blockID);
		world.setBlock(i + 15, j + 1, k + 8, Block.furnaceIdle.blockID);
		world.setBlock(i + 15, j + 1, k + 9, Block.planks.blockID);
		world.setBlock(i + 15, j + 1, k + 10, 0);
		world.setBlock(i + 15, j + 1, k + 11, 0);
		world.setBlock(i + 15, j + 1, k + 12, Block.leaves.blockID);
		world.setBlock(i + 15, j + 2, k + 0, Block.leaves.blockID);
		world.setBlock(i + 15, j + 2, k + 1, 0);
		world.setBlock(i + 15, j + 2, k + 2, 0);
		world.setBlock(i + 15, j + 2, k + 3, Block.glass.blockID);
		world.setBlock(i + 15, j + 2, k + 4, 0);
		world.setBlock(i + 15, j + 2, k + 5, 0);
		world.setBlock(i + 15, j + 2, k + 6, 0);
		world.setBlock(i + 15, j + 2, k + 7, 0);
		world.setBlock(i + 15, j + 2, k + 8, 0);
		world.setBlock(i + 15, j + 2, k + 9, Block.glass.blockID);
		world.setBlock(i + 15, j + 2, k + 10, 0);
		world.setBlock(i + 15, j + 2, k + 11, 0);
		world.setBlock(i + 15, j + 2, k + 12, Block.leaves.blockID);
		world.setBlock(i + 15, j + 3, k + 0, 0);
		world.setBlock(i + 15, j + 3, k + 1, 0);
		world.setBlock(i + 15, j + 3, k + 2, 0);
		world.setBlock(i + 15, j + 3, k + 3, Block.planks.blockID);
		world.setBlock(i + 15, j + 3, k + 4, 0);
		world.setBlock(i + 15, j + 3, k + 5, 0);
		world.setBlock(i + 15, j + 3, k + 6, 0);
		world.setBlock(i + 15, j + 3, k + 7, 0);
		world.setBlock(i + 15, j + 3, k + 8, 0);
		world.setBlock(i + 15, j + 3, k + 9, Block.planks.blockID);
		world.setBlock(i + 15, j + 3, k + 10, 0);
		world.setBlock(i + 15, j + 3, k + 11, 0);
		world.setBlock(i + 15, j + 3, k + 12, 0);
		world.setBlock(i + 15, j + 4, k + 0, 0);
		world.setBlock(i + 15, j + 4, k + 1, 0);
		world.setBlock(i + 15, j + 4, k + 2, 0);
		world.setBlock(i + 15, j + 4, k + 3, 0);
		world.setBlock(i + 15, j + 4, k + 4, Block.planks.blockID);
		world.setBlock(i + 15, j + 4, k + 5, Block.planks.blockID);
		world.setBlock(i + 15, j + 4, k + 6, Block.planks.blockID);
		world.setBlock(i + 15, j + 4, k + 7, Block.planks.blockID);
		world.setBlock(i + 15, j + 4, k + 8, Block.planks.blockID);
		world.setBlock(i + 15, j + 4, k + 9, 0);
		world.setBlock(i + 15, j + 4, k + 10, 0);
		world.setBlock(i + 15, j + 4, k + 11, 0);
		world.setBlock(i + 15, j + 4, k + 12, 0);
		world.setBlock(i + 16, j + 0, k + 0, Block.leaves.blockID);
		world.setBlock(i + 16, j + 0, k + 1, 0);
		world.setBlock(i + 16, j + 0, k + 2, 0);
		world.setBlock(i + 16, j + 0, k + 3, Block.planks.blockID);
		world.setBlock(i + 16, j + 0, k + 4, Block.planks.blockID);
		world.setBlock(i + 16, j + 0, k + 5, Block.planks.blockID);
		world.setBlock(i + 16, j + 0, k + 6, Block.planks.blockID);
		world.setBlock(i + 16, j + 0, k + 7, Block.planks.blockID);
		world.setBlock(i + 16, j + 0, k + 8, Block.planks.blockID);
		world.setBlock(i + 16, j + 0, k + 9, Block.planks.blockID);
		world.setBlock(i + 16, j + 0, k + 10, 0);
		world.setBlock(i + 16, j + 0, k + 11, 0);
		world.setBlock(i + 16, j + 0, k + 12, Block.leaves.blockID);
		world.setBlock(i + 16, j + 1, k + 0, Block.leaves.blockID);
		world.setBlock(i + 16, j + 1, k + 1, 0);
		world.setBlock(i + 16, j + 1, k + 2, 0);
		world.setBlock(i + 16, j + 1, k + 3, Block.planks.blockID);
		world.setBlock(i + 16, j + 1, k + 4, Block.planks.blockID);
		world.setBlock(i + 16, j + 1, k + 5, Block.planks.blockID);
		world.setBlock(i + 16, j + 1, k + 7, Block.planks.blockID);
		world.setBlock(i + 16, j + 1, k + 8, Block.planks.blockID);
		world.setBlock(i + 16, j + 1, k + 9, Block.planks.blockID);
		world.setBlock(i + 16, j + 1, k + 10, 0);
		world.setBlock(i + 16, j + 1, k + 11, 0);
		world.setBlock(i + 16, j + 1, k + 12, Block.leaves.blockID);
		world.setBlock(i + 16, j + 2, k + 0, Block.leaves.blockID);
		world.setBlock(i + 16, j + 2, k + 1, 0);
		world.setBlock(i + 16, j + 2, k + 2, 0);
		world.setBlock(i + 16, j + 2, k + 3, Block.glass.blockID);
		world.setBlock(i + 16, j + 2, k + 4, Block.glass.blockID);
		world.setBlock(i + 16, j + 2, k + 5, Block.glass.blockID);
		world.setBlock(i + 16, j + 2, k + 7, Block.glass.blockID);
		world.setBlock(i + 16, j + 2, k + 8, Block.glass.blockID);
		world.setBlock(i + 16, j + 2, k + 9, Block.glass.blockID);
		world.setBlock(i + 16, j + 2, k + 10, 0);
		world.setBlock(i + 16, j + 2, k + 11, 0);
		world.setBlock(i + 16, j + 2, k + 12, Block.leaves.blockID);
		world.setBlock(i + 16, j + 3, k + 0, 0);
		world.setBlock(i + 16, j + 3, k + 1, 0);
		world.setBlock(i + 16, j + 3, k + 2, 0);
		world.setBlock(i + 16, j + 3, k + 3, Block.planks.blockID);
		world.setBlock(i + 16, j + 3, k + 4, Block.planks.blockID);
		world.setBlock(i + 16, j + 3, k + 5, Block.planks.blockID);
		world.setBlock(i + 16, j + 3, k + 6, Block.woodSingleSlab.blockID);
		world.setBlock(i + 16, j + 3, k + 7, Block.planks.blockID);
		world.setBlock(i + 16, j + 3, k + 8, Block.planks.blockID);
		world.setBlock(i + 16, j + 3, k + 9, Block.planks.blockID);
		world.setBlock(i + 16, j + 3, k + 10, 0);
		world.setBlock(i + 16, j + 3, k + 11, 0);
		world.setBlock(i + 16, j + 3, k + 12, 0);
		world.setBlock(i + 16, j + 4, k + 0, 0);
		world.setBlock(i + 16, j + 4, k + 1, 0);
		world.setBlock(i + 16, j + 4, k + 2, 0);
		world.setBlock(i + 16, j + 4, k + 3, 0);
		world.setBlock(i + 16, j + 4, k + 4, 0);
		world.setBlock(i + 16, j + 4, k + 5, 0);
		world.setBlock(i + 16, j + 4, k + 6, 0);
		world.setBlock(i + 16, j + 4, k + 7, 0);
		world.setBlock(i + 16, j + 4, k + 8, 0);
		world.setBlock(i + 16, j + 4, k + 9, 0);
		world.setBlock(i + 16, j + 4, k + 10, 0);
		world.setBlock(i + 16, j + 4, k + 11, 0);
		world.setBlock(i + 16, j + 4, k + 12, 0);
		world.setBlock(i + 17, j + 0, k + 0, Block.leaves.blockID);
		world.setBlock(i + 17, j + 0, k + 1, 0);
		world.setBlock(i + 17, j + 0, k + 2, 0);
		world.setBlock(i + 17, j + 0, k + 3, 0);
		world.setBlock(i + 17, j + 0, k + 4, 0);
		world.setBlock(i + 17, j + 0, k + 5, Block.woodSingleSlab.blockID);
		world.setBlock(i + 17, j + 0, k + 6, Block.woodSingleSlab.blockID);
		world.setBlock(i + 17, j + 0, k + 7, Block.woodSingleSlab.blockID);
		world.setBlock(i + 17, j + 0, k + 8, 0);
		world.setBlock(i + 17, j + 0, k + 9, 0);
		world.setBlock(i + 17, j + 0, k + 10, 0);
		world.setBlock(i + 17, j + 0, k + 11, 0);
		world.setBlock(i + 17, j + 0, k + 12, Block.leaves.blockID);
		world.setBlock(i + 17, j + 1, k + 0, Block.leaves.blockID);
		world.setBlock(i + 17, j + 1, k + 1, 0);
		world.setBlock(i + 17, j + 1, k + 2, 0);
		world.setBlock(i + 17, j + 1, k + 3, 0);
		world.setBlock(i + 17, j + 1, k + 4, 0);
		world.setBlock(i + 17, j + 1, k + 5, 0);
		world.setBlock(i + 17, j + 1, k + 6, 0);
		world.setBlock(i + 17, j + 1, k + 7, 0);
		world.setBlock(i + 17, j + 1, k + 8, 0);
		world.setBlock(i + 17, j + 1, k + 9, 0);
		world.setBlock(i + 17, j + 1, k + 10, 0);
		world.setBlock(i + 17, j + 1, k + 11, 0);
		world.setBlock(i + 17, j + 1, k + 12, Block.leaves.blockID);
		world.setBlock(i + 17, j + 2, k + 0, Block.leaves.blockID);
		world.setBlock(i + 17, j + 2, k + 1, 0);
		world.setBlock(i + 17, j + 2, k + 2, 0);
		world.setBlock(i + 17, j + 2, k + 3, 0);
		world.setBlock(i + 17, j + 2, k + 4, 0);
		world.setBlock(i + 17, j + 2, k + 5, 0);
		world.setBlock(i + 17, j + 2, k + 6, 0);
		world.setBlock(i + 17, j + 2, k + 7, 0);
		world.setBlock(i + 17, j + 2, k + 8, 0);
		world.setBlock(i + 17, j + 2, k + 9, 0);
		world.setBlock(i + 17, j + 2, k + 10, 0);
		world.setBlock(i + 17, j + 2, k + 11, 0);
		world.setBlock(i + 17, j + 2, k + 12, Block.leaves.blockID);
		world.setBlock(i + 17, j + 3, k + 0, 0);
		world.setBlock(i + 17, j + 3, k + 1, 0);
		world.setBlock(i + 17, j + 3, k + 2, 0);
		world.setBlock(i + 17, j + 3, k + 3, 0);
		world.setBlock(i + 17, j + 3, k + 4, 0);
		world.setBlock(i + 17, j + 3, k + 5, 0);
		world.setBlock(i + 17, j + 3, k + 7, 0);
		world.setBlock(i + 17, j + 3, k + 8, 0);
		world.setBlock(i + 17, j + 3, k + 9, 0);
		world.setBlock(i + 17, j + 3, k + 10, 0);
		world.setBlock(i + 17, j + 3, k + 11, 0);
		world.setBlock(i + 17, j + 3, k + 12, 0);
		world.setBlock(i + 17, j + 4, k + 0, 0);
		world.setBlock(i + 17, j + 4, k + 1, 0);
		world.setBlock(i + 17, j + 4, k + 2, 0);
		world.setBlock(i + 17, j + 4, k + 3, 0);
		world.setBlock(i + 17, j + 4, k + 4, 0);
		world.setBlock(i + 17, j + 4, k + 5, 0);
		world.setBlock(i + 17, j + 4, k + 6, 0);
		world.setBlock(i + 17, j + 4, k + 7, 0);
		world.setBlock(i + 17, j + 4, k + 8, 0);
		world.setBlock(i + 17, j + 4, k + 9, 0);
		world.setBlock(i + 17, j + 4, k + 10, 0);
		world.setBlock(i + 17, j + 4, k + 11, 0);
		world.setBlock(i + 17, j + 4, k + 12, 0);
		world.setBlock(i + 18, j + 0, k + 0, Block.leaves.blockID);
		world.setBlock(i + 18, j + 0, k + 1, 0);
		world.setBlock(i + 18, j + 0, k + 2, 0);
		world.setBlock(i + 18, j + 0, k + 3, 0);
		world.setBlock(i + 18, j + 0, k + 4, 0);
		world.setBlock(i + 18, j + 0, k + 5, 0);
		world.setBlock(i + 18, j + 0, k + 6, 0);
		world.setBlock(i + 18, j + 0, k + 7, 0);
		world.setBlock(i + 18, j + 0, k + 8, 0);
		world.setBlock(i + 18, j + 0, k + 9, 0);
		world.setBlock(i + 18, j + 0, k + 10, 0);
		world.setBlock(i + 18, j + 0, k + 11, 0);
		world.setBlock(i + 18, j + 0, k + 12, Block.leaves.blockID);
		world.setBlock(i + 18, j + 1, k + 0, Block.leaves.blockID);
		world.setBlock(i + 18, j + 1, k + 1, 0);
		world.setBlock(i + 18, j + 1, k + 2, 0);
		world.setBlock(i + 18, j + 1, k + 3, 0);
		world.setBlock(i + 18, j + 1, k + 4, 0);
		world.setBlock(i + 18, j + 1, k + 5, 0);
		world.setBlock(i + 18, j + 1, k + 6, 0);
		world.setBlock(i + 18, j + 1, k + 7, 0);
		world.setBlock(i + 18, j + 1, k + 8, 0);
		world.setBlock(i + 18, j + 1, k + 9, 0);
		world.setBlock(i + 18, j + 1, k + 10, 0);
		world.setBlock(i + 18, j + 1, k + 11, 0);
		world.setBlock(i + 18, j + 1, k + 12, Block.leaves.blockID);
		world.setBlock(i + 18, j + 2, k + 0, Block.leaves.blockID);
		world.setBlock(i + 18, j + 2, k + 1, 0);
		world.setBlock(i + 18, j + 2, k + 2, 0);
		world.setBlock(i + 18, j + 2, k + 3, 0);
		world.setBlock(i + 18, j + 2, k + 4, 0);
		world.setBlock(i + 18, j + 2, k + 5, 0);
		world.setBlock(i + 18, j + 2, k + 6, 0);
		world.setBlock(i + 18, j + 2, k + 7, 0);
		world.setBlock(i + 18, j + 2, k + 8, 0);
		world.setBlock(i + 18, j + 2, k + 9, 0);
		world.setBlock(i + 18, j + 2, k + 10, 0);
		world.setBlock(i + 18, j + 2, k + 11, 0);
		world.setBlock(i + 18, j + 2, k + 12, Block.leaves.blockID);
		world.setBlock(i + 18, j + 3, k + 0, 0);
		world.setBlock(i + 18, j + 3, k + 1, 0);
		world.setBlock(i + 18, j + 3, k + 2, 0);
		world.setBlock(i + 18, j + 3, k + 3, 0);
		world.setBlock(i + 18, j + 3, k + 4, 0);
		world.setBlock(i + 18, j + 3, k + 5, 0);
		world.setBlock(i + 18, j + 3, k + 6, 0);
		world.setBlock(i + 18, j + 3, k + 7, 0);
		world.setBlock(i + 18, j + 3, k + 8, 0);
		world.setBlock(i + 18, j + 3, k + 9, 0);
		world.setBlock(i + 18, j + 3, k + 10, 0);
		world.setBlock(i + 18, j + 3, k + 11, 0);
		world.setBlock(i + 18, j + 3, k + 12, 0);
		world.setBlock(i + 18, j + 4, k + 0, 0);
		world.setBlock(i + 18, j + 4, k + 1, 0);
		world.setBlock(i + 18, j + 4, k + 2, 0);
		world.setBlock(i + 18, j + 4, k + 3, 0);
		world.setBlock(i + 18, j + 4, k + 4, 0);
		world.setBlock(i + 18, j + 4, k + 5, 0);
		world.setBlock(i + 18, j + 4, k + 6, 0);
		world.setBlock(i + 18, j + 4, k + 7, 0);
		world.setBlock(i + 18, j + 4, k + 8, 0);
		world.setBlock(i + 18, j + 4, k + 9, 0);
		world.setBlock(i + 18, j + 4, k + 10, 0);
		world.setBlock(i + 18, j + 4, k + 11, 0);
		world.setBlock(i + 18, j + 4, k + 12, 0);
		world.setBlock(i + 19, j + 0, k + 0, Block.leaves.blockID);
		world.setBlock(i + 19, j + 0, k + 1, Block.leaves.blockID);
		world.setBlock(i + 19, j + 0, k + 2, Block.leaves.blockID);
		world.setBlock(i + 19, j + 0, k + 3, Block.leaves.blockID);
		world.setBlock(i + 19, j + 0, k + 4, Block.leaves.blockID);
		world.setBlock(i + 19, j + 0, k + 5, 0);
		world.setBlock(i + 19, j + 0, k + 6, 0);
		world.setBlock(i + 19, j + 0, k + 7, 0);
		world.setBlock(i + 19, j + 0, k + 8, Block.leaves.blockID);
		world.setBlock(i + 19, j + 0, k + 9, Block.leaves.blockID);
		world.setBlock(i + 19, j + 0, k + 10, Block.leaves.blockID);
		world.setBlock(i + 19, j + 0, k + 11, Block.leaves.blockID);
		world.setBlock(i + 19, j + 0, k + 12, Block.leaves.blockID);
		world.setBlock(i + 19, j + 1, k + 0, Block.leaves.blockID);
		world.setBlock(i + 19, j + 1, k + 1, Block.leaves.blockID);
		world.setBlock(i + 19, j + 1, k + 2, Block.leaves.blockID);
		world.setBlock(i + 19, j + 1, k + 3, Block.leaves.blockID);
		world.setBlock(i + 19, j + 1, k + 4, Block.leaves.blockID);
		world.setBlock(i + 19, j + 1, k + 5, 0);
		world.setBlock(i + 19, j + 1, k + 6, 0);
		world.setBlock(i + 19, j + 1, k + 7, 0);
		world.setBlock(i + 19, j + 1, k + 8, Block.leaves.blockID);
		world.setBlock(i + 19, j + 1, k + 9, Block.leaves.blockID);
		world.setBlock(i + 19, j + 1, k + 10, Block.leaves.blockID);
		world.setBlock(i + 19, j + 1, k + 11, Block.leaves.blockID);
		world.setBlock(i + 19, j + 1, k + 12, Block.leaves.blockID);
		world.setBlock(i + 19, j + 2, k + 0, Block.leaves.blockID);
		world.setBlock(i + 19, j + 2, k + 1, Block.leaves.blockID);
		world.setBlock(i + 19, j + 2, k + 2, Block.leaves.blockID);
		world.setBlock(i + 19, j + 2, k + 3, Block.leaves.blockID);
		world.setBlock(i + 19, j + 2, k + 4, Block.leaves.blockID);
		world.setBlock(i + 19, j + 2, k + 5, Block.leaves.blockID);
		world.setBlock(i + 19, j + 2, k + 6, 0);
		world.setBlock(i + 19, j + 2, k + 7, Block.leaves.blockID);
		world.setBlock(i + 19, j + 2, k + 8, Block.leaves.blockID);
		world.setBlock(i + 19, j + 2, k + 9, Block.leaves.blockID);
		world.setBlock(i + 19, j + 2, k + 10, Block.leaves.blockID);
		world.setBlock(i + 19, j + 2, k + 11, Block.leaves.blockID);
		world.setBlock(i + 19, j + 2, k + 12, Block.leaves.blockID);
		world.setBlock(i + 19, j + 3, k + 0, 0);
		world.setBlock(i + 19, j + 3, k + 1, 0);
		world.setBlock(i + 19, j + 3, k + 2, 0);
		world.setBlock(i + 19, j + 3, k + 3, 0);
		world.setBlock(i + 19, j + 3, k + 4, 0);
		world.setBlock(i + 19, j + 3, k + 5, 0);
		world.setBlock(i + 19, j + 3, k + 6, Block.leaves.blockID);
		world.setBlock(i + 19, j + 3, k + 7, 0);
		world.setBlock(i + 19, j + 3, k + 8, 0);
		world.setBlock(i + 19, j + 3, k + 9, 0);
		world.setBlock(i + 19, j + 3, k + 10, 0);
		world.setBlock(i + 19, j + 3, k + 11, 0);
		world.setBlock(i + 19, j + 3, k + 12, 0);
		world.setBlock(i + 19, j + 4, k + 0, 0);
		world.setBlock(i + 19, j + 4, k + 1, 0);
		world.setBlock(i + 19, j + 4, k + 2, 0);
		world.setBlock(i + 19, j + 4, k + 3, 0);
		world.setBlock(i + 19, j + 4, k + 4, 0);
		world.setBlock(i + 19, j + 4, k + 5, 0);
		world.setBlock(i + 19, j + 4, k + 6, 0);
		world.setBlock(i + 19, j + 4, k + 7, 0);
		world.setBlock(i + 19, j + 4, k + 8, 0);
		world.setBlock(i + 19, j + 4, k + 9, 0);
		world.setBlock(i + 19, j + 4, k + 10, 0);
		world.setBlock(i + 19, j + 4, k + 11, 0);
		world.setBlock(i + 19, j + 4, k + 12, 0);
		world.setBlock(i + 4, j + 1, k + 4, Block.crops.blockID);
		world.setBlock(i + 4, j + 1, k + 5, Block.crops.blockID);
		world.setBlock(i + 4, j + 1, k + 6, Block.crops.blockID);
		world.setBlock(i + 4, j + 1, k + 7, Block.crops.blockID);
		world.setBlock(i + 4, j + 1, k + 8, Block.crops.blockID);
		world.setBlock(i + 5, j + 0, k + 4, Block.waterStill.blockID);
		world.setBlock(i + 5, j + 0, k + 5, Block.waterStill.blockID);
		world.setBlock(i + 5, j + 0, k + 6, Block.waterStill.blockID);
		world.setBlock(i + 5, j + 0, k + 7, Block.waterStill.blockID);
		world.setBlock(i + 5, j + 0, k + 8, Block.waterStill.blockID);
		world.setBlock(i + 6, j + 1, k + 4, Block.crops.blockID);
		world.setBlock(i + 6, j + 1, k + 5, Block.crops.blockID);
		world.setBlock(i + 6, j + 1, k + 6, Block.crops.blockID);
		world.setBlock(i + 6, j + 1, k + 7, Block.crops.blockID);
		world.setBlock(i + 6, j + 1, k + 8, Block.crops.blockID);
		world.setBlock(i + 14, j + 2, k + 5, Block.pressurePlatePlanks.blockID);
		world.setBlock(i + 16, j + 1, k + 6, Block.doorWood.blockID, 2, 0);
		world.setBlock(i + 16, j + 2, k + 6, Block.doorWood.blockID, 8, 0);
		world.setBlock(i + 17, j + 3, k + 6, Block.torchWood.blockID);

		return true;
	}
}