/*
*** MADE BY MITHION'S .SCHEMATIC TO JAVA CONVERTING TOOL v1.6 ***
*/

package com.MixedCraft.gen;
import java.util.Random;

import net.minecraft.block.Block;
import net.minecraft.init.Blocks;
import net.minecraft.world.World;
import net.minecraft.world.gen.feature.WorldGenerator;

public class House1 extends WorldGenerator
{
	public House1() { }

	public boolean generate(World world, Random rand, int i, int j, int k) {
		world.setBlock(i + 0, j + 0, k + 0, Blocks.leaves);
		world.setBlock(i + 0, j + 0, k + 1, Blocks.leaves);
		world.setBlock(i + 0, j + 0, k + 2, Blocks.leaves);
		world.setBlock(i + 0, j + 0, k + 3, Blocks.leaves);
		world.setBlock(i + 0, j + 0, k + 4, Blocks.leaves);
		world.setBlock(i + 0, j + 0, k + 5, Blocks.leaves);
		world.setBlock(i + 0, j + 0, k + 6, Blocks.leaves);
		world.setBlock(i + 0, j + 0, k + 7, Blocks.leaves);
		world.setBlock(i + 0, j + 0, k + 8, Blocks.leaves);
		world.setBlock(i + 0, j + 0, k + 9, Blocks.leaves);
		world.setBlock(i + 0, j + 0, k + 10, Blocks.leaves);
		world.setBlock(i + 0, j + 0, k + 11, Blocks.leaves);
		world.setBlock(i + 0, j + 0, k + 12, Blocks.leaves);
		world.setBlock(i + 0, j + 1, k + 0, Blocks.leaves);
		world.setBlock(i + 0, j + 1, k + 1, Blocks.leaves);
		world.setBlock(i + 0, j + 1, k + 2, Blocks.leaves);
		world.setBlock(i + 0, j + 1, k + 3, Blocks.leaves);
		world.setBlock(i + 0, j + 1, k + 4, Blocks.leaves);
		world.setBlock(i + 0, j + 1, k + 5, Blocks.leaves);
		world.setBlock(i + 0, j + 1, k + 6, Blocks.leaves);
		world.setBlock(i + 0, j + 1, k + 7, Blocks.leaves);
		world.setBlock(i + 0, j + 1, k + 8, Blocks.leaves);
		world.setBlock(i + 0, j + 1, k + 9, Blocks.leaves);
		world.setBlock(i + 0, j + 1, k + 10, Blocks.leaves);
		world.setBlock(i + 0, j + 1, k + 11, Blocks.leaves);
		world.setBlock(i + 0, j + 1, k + 12, Blocks.leaves);
		world.setBlock(i + 0, j + 2, k + 0, Blocks.leaves);
		world.setBlock(i + 0, j + 2, k + 1, Blocks.leaves);
		world.setBlock(i + 0, j + 2, k + 2, Blocks.leaves);
		world.setBlock(i + 0, j + 2, k + 3, Blocks.leaves);
		world.setBlock(i + 0, j + 2, k + 4, Blocks.leaves);
		world.setBlock(i + 0, j + 2, k + 5, Blocks.leaves);
		world.setBlock(i + 0, j + 2, k + 6, Blocks.leaves);
		world.setBlock(i + 0, j + 2, k + 7, Blocks.leaves);
		world.setBlock(i + 0, j + 2, k + 8, Blocks.leaves);
		world.setBlock(i + 0, j + 2, k + 9, Blocks.leaves);
		world.setBlock(i + 0, j + 2, k + 10, Blocks.leaves);
		world.setBlock(i + 0, j + 2, k + 11, Blocks.leaves);
		world.setBlock(i + 0, j + 2, k + 12, Blocks.leaves);
		world.setBlock(i + 0, j + 3, k + 0, null, 0, k);
		world.setBlock(i + 0, j + 3, k + 1, null, 0, k);
		world.setBlock(i + 0, j + 3, k + 2, null, 0, k);
		world.setBlock(i + 0, j + 3, k + 3, null, 0, k);
		world.setBlock(i + 0, j + 3, k + 4, null, 0, k);
		world.setBlock(i + 0, j + 3, k + 5, null, 0, k);
		world.setBlock(i + 0, j + 3, k + 6, null, 0, k);
		world.setBlock(i + 0, j + 3, k + 7, null, 0, k);
		world.setBlock(i + 0, j + 3, k + 8, null, 0, k);
		world.setBlock(i + 0, j + 3, k + 9, null, 0, k);
		world.setBlock(i + 0, j + 3, k + 10, null, 0, k);
		world.setBlock(i + 0, j + 3, k + 11, null, 0, k);
		world.setBlock(i + 0, j + 3, k + 12, null, 0, k);
		world.setBlock(i + 0, j + 4, k + 0, null, 0, k);
		world.setBlock(i + 0, j + 4, k + 1, null, 0, k);
		world.setBlock(i + 0, j + 4, k + 2, null, 0, k);
		world.setBlock(i + 0, j + 4, k + 3, null, 0, k);
		world.setBlock(i + 0, j + 4, k + 4, null, 0, k);
		world.setBlock(i + 0, j + 4, k + 5, null, 0, k);
		world.setBlock(i + 0, j + 4, k + 6, null, 0, k);
		world.setBlock(i + 0, j + 4, k + 7, null, 0, k);
		world.setBlock(i + 0, j + 4, k + 8, null, 0, k);
		world.setBlock(i + 0, j + 4, k + 9, null, 0, k);
		world.setBlock(i + 0, j + 4, k + 10, null, 0, k);
		world.setBlock(i + 0, j + 4, k + 11, null, 0, k);
		world.setBlock(i + 0, j + 4, k + 12, null, 0, k);
		world.setBlock(i + 1, j + 0, k + 0, Blocks.leaves);
		world.setBlock(i + 1, j + 0, k + 1, null, 0, k);
		world.setBlock(i + 1, j + 0, k + 2, null, 0, k);
		world.setBlock(i + 1, j + 0, k + 3, null, 0, k);
		world.setBlock(i + 1, j + 0, k + 4, null, 0, k);
		world.setBlock(i + 1, j + 0, k + 5, null, 0, k);
		world.setBlock(i + 1, j + 0, k + 6, null, 0, k);
		world.setBlock(i + 1, j + 0, k + 7, null, 0, k);
		world.setBlock(i + 1, j + 0, k + 8, null, 0, k);
		world.setBlock(i + 1, j + 0, k + 9, null, 0, k);
		world.setBlock(i + 1, j + 0, k + 10, null, 0, k);
		world.setBlock(i + 1, j + 0, k + 11, null, 0, k);
		world.setBlock(i + 1, j + 0, k + 12, Blocks.leaves);
		world.setBlock(i + 1, j + 1, k + 0, Blocks.leaves);
		world.setBlock(i + 1, j + 1, k + 1, null, 0, k);
		world.setBlock(i + 1, j + 1, k + 2, null, 0, k);
		world.setBlock(i + 1, j + 1, k + 3, null, 0, k);
		world.setBlock(i + 1, j + 1, k + 4, null, 0, k);
		world.setBlock(i + 1, j + 1, k + 5, null, 0, k);
		world.setBlock(i + 1, j + 1, k + 6, null, 0, k);
		world.setBlock(i + 1, j + 1, k + 7, null, 0, k);
		world.setBlock(i + 1, j + 1, k + 8, null, 0, k);
		world.setBlock(i + 1, j + 1, k + 9, null, 0, k);
		world.setBlock(i + 1, j + 1, k + 10, null, 0, k);
		world.setBlock(i + 1, j + 1, k + 11, null, 0, k);
		world.setBlock(i + 1, j + 1, k + 12, Blocks.leaves);
		world.setBlock(i + 1, j + 2, k + 0, Blocks.leaves);
		world.setBlock(i + 1, j + 2, k + 1, null, 0, k);
		world.setBlock(i + 1, j + 2, k + 2, null, 0, k);
		world.setBlock(i + 1, j + 2, k + 3, null, 0, k);
		world.setBlock(i + 1, j + 2, k + 4, null, 0, k);
		world.setBlock(i + 1, j + 2, k + 5, null, 0, k);
		world.setBlock(i + 1, j + 2, k + 6, null, 0, k);
		world.setBlock(i + 1, j + 2, k + 7, null, 0, k);
		world.setBlock(i + 1, j + 2, k + 8, null, 0, k);
		world.setBlock(i + 1, j + 2, k + 9, null, 0, k);
		world.setBlock(i + 1, j + 2, k + 10, null, 0, k);
		world.setBlock(i + 1, j + 2, k + 11, null, 0, k);
		world.setBlock(i + 1, j + 2, k + 12, Blocks.leaves);
		world.setBlock(i + 1, j + 3, k + 0, null, 0, k);
		world.setBlock(i + 1, j + 3, k + 1, null, 0, k);
		world.setBlock(i + 1, j + 3, k + 2, null, 0, k);
		world.setBlock(i + 1, j + 3, k + 3, null, 0, k);
		world.setBlock(i + 1, j + 3, k + 4, null, 0, k);
		world.setBlock(i + 1, j + 3, k + 5, null, 0, k);
		world.setBlock(i + 1, j + 3, k + 6, null, 0, k);
		world.setBlock(i + 1, j + 3, k + 7, null, 0, k);
		world.setBlock(i + 1, j + 3, k + 8, null, 0, k);
		world.setBlock(i + 1, j + 3, k + 9, null, 0, k);
		world.setBlock(i + 1, j + 3, k + 10, null, 0, k);
		world.setBlock(i + 1, j + 3, k + 11, null, 0, k);
		world.setBlock(i + 1, j + 3, k + 12, null, 0, k);
		world.setBlock(i + 1, j + 4, k + 0, null, 0, k);
		world.setBlock(i + 1, j + 4, k + 1, null, 0, k);
		world.setBlock(i + 1, j + 4, k + 2, null, 0, k);
		world.setBlock(i + 1, j + 4, k + 3, null, 0, k);
		world.setBlock(i + 1, j + 4, k + 4, null, 0, k);
		world.setBlock(i + 1, j + 4, k + 5, null, 0, k);
		world.setBlock(i + 1, j + 4, k + 6, null, 0, k);
		world.setBlock(i + 1, j + 4, k + 7, null, 0, k);
		world.setBlock(i + 1, j + 4, k + 8, null, 0, k);
		world.setBlock(i + 1, j + 4, k + 9, null, 0, k);
		world.setBlock(i + 1, j + 4, k + 10, null, 0, k);
		world.setBlock(i + 1, j + 4, k + 11, null, 0, k);
		world.setBlock(i + 1, j + 4, k + 12, null, 0, k);
		world.setBlock(i + 2, j + 0, k + 0, Blocks.leaves);
		world.setBlock(i + 2, j + 0, k + 1, null, 0, k);
		world.setBlock(i + 2, j + 0, k + 2, null, 0, k);
		world.setBlock(i + 2, j + 0, k + 3, null, 0, k);
		world.setBlock(i + 2, j + 0, k + 4, null, 0, k);
		world.setBlock(i + 2, j + 0, k + 5, null, 0, k);
		world.setBlock(i + 2, j + 0, k + 6, null, 0, k);
		world.setBlock(i + 2, j + 0, k + 7, null, 0, k);
		world.setBlock(i + 2, j + 0, k + 8, null, 0, k);
		world.setBlock(i + 2, j + 0, k + 9, null, 0, k);
		world.setBlock(i + 2, j + 0, k + 10, null, 0, k);
		world.setBlock(i + 2, j + 0, k + 11, null, 0, k);
		world.setBlock(i + 2, j + 0, k + 12, Blocks.leaves);
		world.setBlock(i + 2, j + 1, k + 0, Blocks.leaves);
		world.setBlock(i + 2, j + 1, k + 1, null, 0, k);
		world.setBlock(i + 2, j + 1, k + 2, null, 0, k);
		world.setBlock(i + 2, j + 1, k + 3, null, 0, k);
		world.setBlock(i + 2, j + 1, k + 4, null, 0, k);
		world.setBlock(i + 2, j + 1, k + 5, null, 0, k);
		world.setBlock(i + 2, j + 1, k + 6, null, 0, k);
		world.setBlock(i + 2, j + 1, k + 7, null, 0, k);
		world.setBlock(i + 2, j + 1, k + 8, null, 0, k);
		world.setBlock(i + 2, j + 1, k + 9, null, 0, k);
		world.setBlock(i + 2, j + 1, k + 10, null, 0, k);
		world.setBlock(i + 2, j + 1, k + 11, null, 0, k);
		world.setBlock(i + 2, j + 1, k + 12, Blocks.leaves);
		world.setBlock(i + 2, j + 2, k + 0, Blocks.leaves);
		world.setBlock(i + 2, j + 2, k + 1, null, 0, k);
		world.setBlock(i + 2, j + 2, k + 2, null, 0, k);
		world.setBlock(i + 2, j + 2, k + 3, null, 0, k);
		world.setBlock(i + 2, j + 2, k + 4, null, 0, k);
		world.setBlock(i + 2, j + 2, k + 5, null, 0, k);
		world.setBlock(i + 2, j + 2, k + 6, null, 0, k);
		world.setBlock(i + 2, j + 2, k + 7, null, 0, k);
		world.setBlock(i + 2, j + 2, k + 8, null, 0, k);
		world.setBlock(i + 2, j + 2, k + 9, null, 0, k);
		world.setBlock(i + 2, j + 2, k + 10, null, 0, k);
		world.setBlock(i + 2, j + 2, k + 11, null, 0, k);
		world.setBlock(i + 2, j + 2, k + 12, Blocks.leaves);
		world.setBlock(i + 2, j + 3, k + 0, null, 0, k);
		world.setBlock(i + 2, j + 3, k + 1, null, 0, k);
		world.setBlock(i + 2, j + 3, k + 2, null, 0, k);
		world.setBlock(i + 2, j + 3, k + 3, null, 0, k);
		world.setBlock(i + 2, j + 3, k + 4, null, 0, k);
		world.setBlock(i + 2, j + 3, k + 5, null, 0, k);
		world.setBlock(i + 2, j + 3, k + 6, null, 0, k);
		world.setBlock(i + 2, j + 3, k + 7, null, 0, k);
		world.setBlock(i + 2, j + 3, k + 8, null, 0, k);
		world.setBlock(i + 2, j + 3, k + 9, null, 0, k);
		world.setBlock(i + 2, j + 3, k + 10, null, 0, k);
		world.setBlock(i + 2, j + 3, k + 11, null, 0, k);
		world.setBlock(i + 2, j + 3, k + 12, null, 0, k);
		world.setBlock(i + 2, j + 4, k + 0, null, 0, k);
		world.setBlock(i + 2, j + 4, k + 1, null, 0, k);
		world.setBlock(i + 2, j + 4, k + 2, null, 0, k);
		world.setBlock(i + 2, j + 4, k + 3, null, 0, k);
		world.setBlock(i + 2, j + 4, k + 4, null, 0, k);
		world.setBlock(i + 2, j + 4, k + 5, null, 0, k);
		world.setBlock(i + 2, j + 4, k + 6, null, 0, k);
		world.setBlock(i + 2, j + 4, k + 7, null, 0, k);
		world.setBlock(i + 2, j + 4, k + 8, null, 0, k);
		world.setBlock(i + 2, j + 4, k + 9, null, 0, k);
		world.setBlock(i + 2, j + 4, k + 10, null, 0, k);
		world.setBlock(i + 2, j + 4, k + 11, null, 0, k);
		world.setBlock(i + 2, j + 4, k + 12, null, 0, k);
		world.setBlock(i + 3, j + 0, k + 0, Blocks.leaves);
		world.setBlock(i + 3, j + 0, k + 1, null, 0, k);
		world.setBlock(i + 3, j + 0, k + 2, null, 0, k);
		world.setBlock(i + 3, j + 0, k + 3, Blocks.log);
		world.setBlock(i + 3, j + 0, k + 4, Blocks.log);
		world.setBlock(i + 3, j + 0, k + 5, Blocks.log);
		world.setBlock(i + 3, j + 0, k + 6, Blocks.log);
		world.setBlock(i + 3, j + 0, k + 7, Blocks.log);
		world.setBlock(i + 3, j + 0, k + 8, Blocks.log);
		world.setBlock(i + 3, j + 0, k + 9, Blocks.log);
		world.setBlock(i + 3, j + 0, k + 10, null, 0, k);
		world.setBlock(i + 3, j + 0, k + 11, null, 0, k);
		world.setBlock(i + 3, j + 0, k + 12, Blocks.leaves);
		world.setBlock(i + 3, j + 1, k + 0, Blocks.leaves);
		world.setBlock(i + 3, j + 1, k + 1, null, 0, k);
		world.setBlock(i + 3, j + 1, k + 2, null, 0, k);
		world.setBlock(i + 3, j + 1, k + 3, null, 0, k);
		world.setBlock(i + 3, j + 1, k + 4, null, 0, k);
		world.setBlock(i + 3, j + 1, k + 5, null, 0, k);
		world.setBlock(i + 3, j + 1, k + 6, null, 0, k);
		world.setBlock(i + 3, j + 1, k + 7, null, 0, k);
		world.setBlock(i + 3, j + 1, k + 8, null, 0, k);
		world.setBlock(i + 3, j + 1, k + 9, null, 0, k);
		world.setBlock(i + 3, j + 1, k + 10, null, 0, k);
		world.setBlock(i + 3, j + 1, k + 11, null, 0, k);
		world.setBlock(i + 3, j + 1, k + 12, Blocks.leaves);
		world.setBlock(i + 3, j + 2, k + 0, Blocks.leaves);
		world.setBlock(i + 3, j + 2, k + 1, null, 0, k);
		world.setBlock(i + 3, j + 2, k + 2, null, 0, k);
		world.setBlock(i + 3, j + 2, k + 3, null, 0, k);
		world.setBlock(i + 3, j + 2, k + 4, null, 0, k);
		world.setBlock(i + 3, j + 2, k + 5, null, 0, k);
		world.setBlock(i + 3, j + 2, k + 6, null, 0, k);
		world.setBlock(i + 3, j + 2, k + 7, null, 0, k);
		world.setBlock(i + 3, j + 2, k + 8, null, 0, k);
		world.setBlock(i + 3, j + 2, k + 9, null, 0, k);
		world.setBlock(i + 3, j + 2, k + 10, null, 0, k);
		world.setBlock(i + 3, j + 2, k + 11, null, 0, k);
		world.setBlock(i + 3, j + 2, k + 12, Blocks.leaves);
		world.setBlock(i + 3, j + 3, k + 0, null, 0, k);
		world.setBlock(i + 3, j + 3, k + 1, null, 0, k);
		world.setBlock(i + 3, j + 3, k + 2, null, 0, k);
		world.setBlock(i + 3, j + 3, k + 3, null, 0, k);
		world.setBlock(i + 3, j + 3, k + 4, null, 0, k);
		world.setBlock(i + 3, j + 3, k + 5, null, 0, k);
		world.setBlock(i + 3, j + 3, k + 6, null, 0, k);
		world.setBlock(i + 3, j + 3, k + 7, null, 0, k);
		world.setBlock(i + 3, j + 3, k + 8, null, 0, k);
		world.setBlock(i + 3, j + 3, k + 9, null, 0, k);
		world.setBlock(i + 3, j + 3, k + 10, null, 0, k);
		world.setBlock(i + 3, j + 3, k + 11, null, 0, k);
		world.setBlock(i + 3, j + 3, k + 12, null, 0, k);
		world.setBlock(i + 3, j + 4, k + 0, null, 0, k);
		world.setBlock(i + 3, j + 4, k + 1, null, 0, k);
		world.setBlock(i + 3, j + 4, k + 2, null, 0, k);
		world.setBlock(i + 3, j + 4, k + 3, null, 0, k);
		world.setBlock(i + 3, j + 4, k + 4, null, 0, k);
		world.setBlock(i + 3, j + 4, k + 5, null, 0, k);
		world.setBlock(i + 3, j + 4, k + 6, null, 0, k);
		world.setBlock(i + 3, j + 4, k + 7, null, 0, k);
		world.setBlock(i + 3, j + 4, k + 8, null, 0, k);
		world.setBlock(i + 3, j + 4, k + 9, null, 0, k);
		world.setBlock(i + 3, j + 4, k + 10, null, 0, k);
		world.setBlock(i + 3, j + 4, k + 11, null, 0, k);
		world.setBlock(i + 3, j + 4, k + 12, null, 0, k);
		world.setBlock(i + 4, j + 0, k + 0, Blocks.leaves);
		world.setBlock(i + 4, j + 0, k + 1, null, 0, k);
		world.setBlock(i + 4, j + 0, k + 2, null, 0, k);
		world.setBlock(i + 4, j + 0, k + 3, Blocks.log);
		world.setBlock(i + 4, j + 0, k + 4, Blocks.farmland);
		world.setBlock(i + 4, j + 0, k + 5, Blocks.farmland);
		world.setBlock(i + 4, j + 0, k + 6, Blocks.farmland);
		world.setBlock(i + 4, j + 0, k + 7, Blocks.farmland);
		world.setBlock(i + 4, j + 0, k + 8, Blocks.farmland);
		world.setBlock(i + 4, j + 0, k + 9, Blocks.log);
		world.setBlock(i + 4, j + 0, k + 10, null, 0, k);
		world.setBlock(i + 4, j + 0, k + 11, null, 0, k);
		world.setBlock(i + 4, j + 0, k + 12, Blocks.leaves);
		world.setBlock(i + 4, j + 1, k + 0, Blocks.leaves);
		world.setBlock(i + 4, j + 1, k + 1, null, 0, k);
		world.setBlock(i + 4, j + 1, k + 2, null, 0, k);
		world.setBlock(i + 4, j + 1, k + 3, null, 0, k);
		world.setBlock(i + 4, j + 1, k + 9, null, 0, k);
		world.setBlock(i + 4, j + 1, k + 10, null, 0, k);
		world.setBlock(i + 4, j + 1, k + 11, null, 0, k);
		world.setBlock(i + 4, j + 1, k + 12, Blocks.leaves);
		world.setBlock(i + 4, j + 2, k + 0, Blocks.leaves);
		world.setBlock(i + 4, j + 2, k + 1, null, 0, k);
		world.setBlock(i + 4, j + 2, k + 2, null, 0, k);
		world.setBlock(i + 4, j + 2, k + 3, null, 0, k);
		world.setBlock(i + 4, j + 2, k + 4, null, 0, k);
		world.setBlock(i + 4, j + 2, k + 5, null, 0, k);
		world.setBlock(i + 4, j + 2, k + 6, null, 0, k);
		world.setBlock(i + 4, j + 2, k + 7, null, 0, k);
		world.setBlock(i + 4, j + 2, k + 8, null, 0, k);
		world.setBlock(i + 4, j + 2, k + 9, null, 0, k);
		world.setBlock(i + 4, j + 2, k + 10, null, 0, k);
		world.setBlock(i + 4, j + 2, k + 11, null, 0, k);
		world.setBlock(i + 4, j + 2, k + 12, Blocks.leaves);
		world.setBlock(i + 4, j + 3, k + 0, null, 0, k);
		world.setBlock(i + 4, j + 3, k + 1, null, 0, k);
		world.setBlock(i + 4, j + 3, k + 2, null, 0, k);
		world.setBlock(i + 4, j + 3, k + 3, null, 0, k);
		world.setBlock(i + 4, j + 3, k + 4, null, 0, k);
		world.setBlock(i + 4, j + 3, k + 5, null, 0, k);
		world.setBlock(i + 4, j + 3, k + 6, null, 0, k);
		world.setBlock(i + 4, j + 3, k + 7, null, 0, k);
		world.setBlock(i + 4, j + 3, k + 8, null, 0, k);
		world.setBlock(i + 4, j + 3, k + 9, null, 0, k);
		world.setBlock(i + 4, j + 3, k + 10, null, 0, k);
		world.setBlock(i + 4, j + 3, k + 11, null, 0, k);
		world.setBlock(i + 4, j + 3, k + 12, null, 0, k);
		world.setBlock(i + 4, j + 4, k + 0, null, 0, k);
		world.setBlock(i + 4, j + 4, k + 1, null, 0, k);
		world.setBlock(i + 4, j + 4, k + 2, null, 0, k);
		world.setBlock(i + 4, j + 4, k + 3, null, 0, k);
		world.setBlock(i + 4, j + 4, k + 4, null, 0, k);
		world.setBlock(i + 4, j + 4, k + 5, null, 0, k);
		world.setBlock(i + 4, j + 4, k + 6, null, 0, k);
		world.setBlock(i + 4, j + 4, k + 7, null, 0, k);
		world.setBlock(i + 4, j + 4, k + 8, null, 0, k);
		world.setBlock(i + 4, j + 4, k + 9, null, 0, k);
		world.setBlock(i + 4, j + 4, k + 10, null, 0, k);
		world.setBlock(i + 4, j + 4, k + 11, null, 0, k);
		world.setBlock(i + 4, j + 4, k + 12, null, 0, k);
		world.setBlock(i + 5, j + 0, k + 0, Blocks.leaves);
		world.setBlock(i + 5, j + 0, k + 1, null, 0, k);
		world.setBlock(i + 5, j + 0, k + 2, null, 0, k);
		world.setBlock(i + 5, j + 0, k + 3, Blocks.log);
		world.setBlock(i + 5, j + 0, k + 9, Blocks.log);
		world.setBlock(i + 5, j + 0, k + 10, null, 0, k);
		world.setBlock(i + 5, j + 0, k + 11, null, 0, k);
		world.setBlock(i + 5, j + 0, k + 12, Blocks.leaves);
		world.setBlock(i + 5, j + 1, k + 0, Blocks.leaves);
		world.setBlock(i + 5, j + 1, k + 1, null, 0, k);
		world.setBlock(i + 5, j + 1, k + 2, null, 0, k);
		world.setBlock(i + 5, j + 1, k + 3, null, 0, k);
		world.setBlock(i + 5, j + 1, k + 4, null, 0, k);
		world.setBlock(i + 5, j + 1, k + 5, null, 0, k);
		world.setBlock(i + 5, j + 1, k + 6, null, 0, k);
		world.setBlock(i + 5, j + 1, k + 7, null, 0, k);
		world.setBlock(i + 5, j + 1, k + 8, null, 0, k);
		world.setBlock(i + 5, j + 1, k + 9, null, 0, k);
		world.setBlock(i + 5, j + 1, k + 10, null, 0, k);
		world.setBlock(i + 5, j + 1, k + 11, null, 0, k);
		world.setBlock(i + 5, j + 1, k + 12, Blocks.leaves);
		world.setBlock(i + 5, j + 2, k + 0, Blocks.leaves);
		world.setBlock(i + 5, j + 2, k + 1, null, 0, k);
		world.setBlock(i + 5, j + 2, k + 2, null, 0, k);
		world.setBlock(i + 5, j + 2, k + 3, null, 0, k);
		world.setBlock(i + 5, j + 2, k + 4, null, 0, k);
		world.setBlock(i + 5, j + 2, k + 5, null, 0, k);
		world.setBlock(i + 5, j + 2, k + 6, null, 0, k);
		world.setBlock(i + 5, j + 2, k + 7, null, 0, k);
		world.setBlock(i + 5, j + 2, k + 8, null, 0, k);
		world.setBlock(i + 5, j + 2, k + 9, null, 0, k);
		world.setBlock(i + 5, j + 2, k + 10, null, 0, k);
		world.setBlock(i + 5, j + 2, k + 11, null, 0, k);
		world.setBlock(i + 5, j + 2, k + 12, Blocks.leaves);
		world.setBlock(i + 5, j + 3, k + 0, null, 0, k);
		world.setBlock(i + 5, j + 3, k + 1, null, 0, k);
		world.setBlock(i + 5, j + 3, k + 2, null, 0, k);
		world.setBlock(i + 5, j + 3, k + 3, null, 0, k);
		world.setBlock(i + 5, j + 3, k + 4, Blocks.fence);
		world.setBlock(i + 5, j + 3, k + 5, Blocks.fence);
		world.setBlock(i + 5, j + 3, k + 6, Blocks.fence);
		world.setBlock(i + 5, j + 3, k + 7, Blocks.fence);
		world.setBlock(i + 5, j + 3, k + 8, Blocks.fence);
		world.setBlock(i + 5, j + 3, k + 9, null, 0, k);
		world.setBlock(i + 5, j + 3, k + 10, null, 0, k);
		world.setBlock(i + 5, j + 3, k + 11, null, 0, k);
		world.setBlock(i + 5, j + 3, k + 12, null, 0, k);
		world.setBlock(i + 5, j + 4, k + 0, null, 0, k);
		world.setBlock(i + 5, j + 4, k + 1, null, 0, k);
		world.setBlock(i + 5, j + 4, k + 2, null, 0, k);
		world.setBlock(i + 5, j + 4, k + 3, null, 0, k);
		world.setBlock(i + 5, j + 4, k + 4, Blocks.glowstone);
		world.setBlock(i + 5, j + 4, k + 5, Blocks.glowstone);
		world.setBlock(i + 5, j + 4, k + 6, Blocks.glowstone);
		world.setBlock(i + 5, j + 4, k + 7, Blocks.glowstone);
		world.setBlock(i + 5, j + 4, k + 8, Blocks.glowstone);
		world.setBlock(i + 5, j + 4, k + 9, null, 0, k);
		world.setBlock(i + 5, j + 4, k + 10, null, 0, k);
		world.setBlock(i + 5, j + 4, k + 11, null, 0, k);
		world.setBlock(i + 5, j + 4, k + 12, null, 0, k);
		world.setBlock(i + 6, j + 0, k + 0, Blocks.leaves);
		world.setBlock(i + 6, j + 0, k + 1, null, 0, k);
		world.setBlock(i + 6, j + 0, k + 2, null, 0, k);
		world.setBlock(i + 6, j + 0, k + 3, Blocks.log);
		world.setBlock(i + 6, j + 0, k + 4, Blocks.farmland);
		world.setBlock(i + 6, j + 0, k + 5, Blocks.farmland);
		world.setBlock(i + 6, j + 0, k + 6, Blocks.farmland);
		world.setBlock(i + 6, j + 0, k + 7, Blocks.farmland);
		world.setBlock(i + 6, j + 0, k + 8, Blocks.farmland);
		world.setBlock(i + 6, j + 0, k + 9, Blocks.log);
		world.setBlock(i + 6, j + 0, k + 10, null, 0, k);
		world.setBlock(i + 6, j + 0, k + 11, null, 0, k);
		world.setBlock(i + 6, j + 0, k + 12, Blocks.leaves);
		world.setBlock(i + 6, j + 1, k + 0, Blocks.leaves);
		world.setBlock(i + 6, j + 1, k + 1, null, 0, k);
		world.setBlock(i + 6, j + 1, k + 2, null, 0, k);
		world.setBlock(i + 6, j + 1, k + 3, null, 0, k);
		world.setBlock(i + 6, j + 1, k + 9, null, 0, k);
		world.setBlock(i + 6, j + 1, k + 10, null, 0, k);
		world.setBlock(i + 6, j + 1, k + 11, null, 0, k);
		world.setBlock(i + 6, j + 1, k + 12, Blocks.leaves);
		world.setBlock(i + 6, j + 2, k + 0, Blocks.leaves);
		world.setBlock(i + 6, j + 2, k + 1, null, 0, k);
		world.setBlock(i + 6, j + 2, k + 2, null, 0, k);
		world.setBlock(i + 6, j + 2, k + 3, null, 0, k);
		world.setBlock(i + 6, j + 2, k + 4, null, 0, k);
		world.setBlock(i + 6, j + 2, k + 5, null, 0, k);
		world.setBlock(i + 6, j + 2, k + 6, null, 0, k);
		world.setBlock(i + 6, j + 2, k + 7, null, 0, k);
		world.setBlock(i + 6, j + 2, k + 8, null, 0, k);
		world.setBlock(i + 6, j + 2, k + 9, null, 0, k);
		world.setBlock(i + 6, j + 2, k + 10, null, 0, k);
		world.setBlock(i + 6, j + 2, k + 11, null, 0, k);
		world.setBlock(i + 6, j + 2, k + 12, Blocks.leaves);
		world.setBlock(i + 6, j + 3, k + 0, null, 0, k);
		world.setBlock(i + 6, j + 3, k + 1, null, 0, k);
		world.setBlock(i + 6, j + 3, k + 2, null, 0, k);
		world.setBlock(i + 6, j + 3, k + 3, null, 0, k);
		world.setBlock(i + 6, j + 3, k + 4, null, 0, k);
		world.setBlock(i + 6, j + 3, k + 5, null, 0, k);
		world.setBlock(i + 6, j + 3, k + 6, null, 0, k);
		world.setBlock(i + 6, j + 3, k + 7, null, 0, k);
		world.setBlock(i + 6, j + 3, k + 8, null, 0, k);
		world.setBlock(i + 6, j + 3, k + 9, null, 0, k);
		world.setBlock(i + 6, j + 3, k + 10, null, 0, k);
		world.setBlock(i + 6, j + 3, k + 11, null, 0, k);
		world.setBlock(i + 6, j + 3, k + 12, null, 0, k);
		world.setBlock(i + 6, j + 4, k + 0, null, 0, k);
		world.setBlock(i + 6, j + 4, k + 1, null, 0, k);
		world.setBlock(i + 6, j + 4, k + 2, null, 0, k);
		world.setBlock(i + 6, j + 4, k + 3, null, 0, k);
		world.setBlock(i + 6, j + 4, k + 4, null, 0, k);
		world.setBlock(i + 6, j + 4, k + 5, null, 0, k);
		world.setBlock(i + 6, j + 4, k + 6, null, 0, k);
		world.setBlock(i + 6, j + 4, k + 7, null, 0, k);
		world.setBlock(i + 6, j + 4, k + 8, null, 0, k);
		world.setBlock(i + 6, j + 4, k + 9, null, 0, k);
		world.setBlock(i + 6, j + 4, k + 10, null, 0, k);
		world.setBlock(i + 6, j + 4, k + 11, null, 0, k);
		world.setBlock(i + 6, j + 4, k + 12, null, 0, k);
		world.setBlock(i + 7, j + 0, k + 0, Blocks.leaves);
		world.setBlock(i + 7, j + 0, k + 1, null, 0, k);
		world.setBlock(i + 7, j + 0, k + 2, null, 0, k);
		world.setBlock(i + 7, j + 0, k + 3, Blocks.log);
		world.setBlock(i + 7, j + 0, k + 4, Blocks.log);
		world.setBlock(i + 7, j + 0, k + 5, Blocks.log);
		world.setBlock(i + 7, j + 0, k + 6, Blocks.log);
		world.setBlock(i + 7, j + 0, k + 7, Blocks.log);
		world.setBlock(i + 7, j + 0, k + 8, Blocks.log);
		world.setBlock(i + 7, j + 0, k + 9, Blocks.log);
		world.setBlock(i + 7, j + 0, k + 10, null, 0, k);
		world.setBlock(i + 7, j + 0, k + 11, null, 0, k);
		world.setBlock(i + 7, j + 0, k + 12, Blocks.leaves);
		world.setBlock(i + 7, j + 1, k + 0, Blocks.leaves);
		world.setBlock(i + 7, j + 1, k + 1, null, 0, k);
		world.setBlock(i + 7, j + 1, k + 2, null, 0, k);
		world.setBlock(i + 7, j + 1, k + 3, null, 0, k);
		world.setBlock(i + 7, j + 1, k + 4, null, 0, k);
		world.setBlock(i + 7, j + 1, k + 5, null, 0, k);
		world.setBlock(i + 7, j + 1, k + 6, null, 0, k);
		world.setBlock(i + 7, j + 1, k + 7, null, 0, k);
		world.setBlock(i + 7, j + 1, k + 8, null, 0, k);
		world.setBlock(i + 7, j + 1, k + 9, null, 0, k);
		world.setBlock(i + 7, j + 1, k + 10, null, 0, k);
		world.setBlock(i + 7, j + 1, k + 11, null, 0, k);
		world.setBlock(i + 7, j + 1, k + 12, Blocks.leaves);
		world.setBlock(i + 7, j + 2, k + 0, Blocks.leaves);
		world.setBlock(i + 7, j + 2, k + 1, null, 0, k);
		world.setBlock(i + 7, j + 2, k + 2, null, 0, k);
		world.setBlock(i + 7, j + 2, k + 3, null, 0, k);
		world.setBlock(i + 7, j + 2, k + 4, null, 0, k);
		world.setBlock(i + 7, j + 2, k + 5, null, 0, k);
		world.setBlock(i + 7, j + 2, k + 6, null, 0, k);
		world.setBlock(i + 7, j + 2, k + 7, null, 0, k);
		world.setBlock(i + 7, j + 2, k + 8, null, 0, k);
		world.setBlock(i + 7, j + 2, k + 9, null, 0, k);
		world.setBlock(i + 7, j + 2, k + 10, null, 0, k);
		world.setBlock(i + 7, j + 2, k + 11, null, 0, k);
		world.setBlock(i + 7, j + 2, k + 12, Blocks.leaves);
		world.setBlock(i + 7, j + 3, k + 0, null, 0, k);
		world.setBlock(i + 7, j + 3, k + 1, null, 0, k);
		world.setBlock(i + 7, j + 3, k + 2, null, 0, k);
		world.setBlock(i + 7, j + 3, k + 3, null, 0, k);
		world.setBlock(i + 7, j + 3, k + 4, null, 0, k);
		world.setBlock(i + 7, j + 3, k + 5, null, 0, k);
		world.setBlock(i + 7, j + 3, k + 6, null, 0, k);
		world.setBlock(i + 7, j + 3, k + 7, null, 0, k);
		world.setBlock(i + 7, j + 3, k + 8, null, 0, k);
		world.setBlock(i + 7, j + 3, k + 9, null, 0, k);
		world.setBlock(i + 7, j + 3, k + 10, null, 0, k);
		world.setBlock(i + 7, j + 3, k + 11, null, 0, k);
		world.setBlock(i + 7, j + 3, k + 12, null, 0, k);
		world.setBlock(i + 7, j + 4, k + 0, null, 0, k);
		world.setBlock(i + 7, j + 4, k + 1, null, 0, k);
		world.setBlock(i + 7, j + 4, k + 2, null, 0, k);
		world.setBlock(i + 7, j + 4, k + 3, null, 0, k);
		world.setBlock(i + 7, j + 4, k + 4, null, 0, k);
		world.setBlock(i + 7, j + 4, k + 5, null, 0, k);
		world.setBlock(i + 7, j + 4, k + 6, null, 0, k);
		world.setBlock(i + 7, j + 4, k + 7, null, 0, k);
		world.setBlock(i + 7, j + 4, k + 8, null, 0, k);
		world.setBlock(i + 7, j + 4, k + 9, null, 0, k);
		world.setBlock(i + 7, j + 4, k + 10, null, 0, k);
		world.setBlock(i + 7, j + 4, k + 11, null, 0, k);
		world.setBlock(i + 7, j + 4, k + 12, null, 0, k);
		world.setBlock(i + 8, j + 0, k + 0, Blocks.leaves);
		world.setBlock(i + 8, j + 0, k + 1, null, 0, k);
		world.setBlock(i + 8, j + 0, k + 2, null, 0, k);
		world.setBlock(i + 8, j + 0, k + 3, null, 0, k);
		world.setBlock(i + 8, j + 0, k + 4, null, 0, k);
		world.setBlock(i + 8, j + 0, k + 5, null, 0, k);
		world.setBlock(i + 8, j + 0, k + 6, null, 0, k);
		world.setBlock(i + 8, j + 0, k + 7, null, 0, k);
		world.setBlock(i + 8, j + 0, k + 8, null, 0, k);
		world.setBlock(i + 8, j + 0, k + 9, null, 0, k);
		world.setBlock(i + 8, j + 0, k + 10, null, 0, k);
		world.setBlock(i + 8, j + 0, k + 11, null, 0, k);
		world.setBlock(i + 8, j + 0, k + 12, Blocks.leaves);
		world.setBlock(i + 8, j + 1, k + 0, Blocks.leaves);
		world.setBlock(i + 8, j + 1, k + 1, null, 0, k);
		world.setBlock(i + 8, j + 1, k + 2, null, 0, k);
		world.setBlock(i + 8, j + 1, k + 3, null, 0, k);
		world.setBlock(i + 8, j + 1, k + 4, null, 0, k);
		world.setBlock(i + 8, j + 1, k + 5, null, 0, k);
		world.setBlock(i + 8, j + 1, k + 6, null, 0, k);
		world.setBlock(i + 8, j + 1, k + 7, null, 0, k);
		world.setBlock(i + 8, j + 1, k + 8, null, 0, k);
		world.setBlock(i + 8, j + 1, k + 9, null, 0, k);
		world.setBlock(i + 8, j + 1, k + 10, null, 0, k);
		world.setBlock(i + 8, j + 1, k + 11, null, 0, k);
		world.setBlock(i + 8, j + 1, k + 12, Blocks.leaves);
		world.setBlock(i + 8, j + 2, k + 0, Blocks.leaves);
		world.setBlock(i + 8, j + 2, k + 1, null, 0, k);
		world.setBlock(i + 8, j + 2, k + 2, null, 0, k);
		world.setBlock(i + 8, j + 2, k + 3, null, 0, k);
		world.setBlock(i + 8, j + 2, k + 4, null, 0, k);
		world.setBlock(i + 8, j + 2, k + 5, null, 0, k);
		world.setBlock(i + 8, j + 2, k + 6, null, 0, k);
		world.setBlock(i + 8, j + 2, k + 7, null, 0, k);
		world.setBlock(i + 8, j + 2, k + 8, null, 0, k);
		world.setBlock(i + 8, j + 2, k + 9, null, 0, k);
		world.setBlock(i + 8, j + 2, k + 10, null, 0, k);
		world.setBlock(i + 8, j + 2, k + 11, null, 0, k);
		world.setBlock(i + 8, j + 2, k + 12, Blocks.leaves);
		world.setBlock(i + 8, j + 3, k + 0, null, 0, k);
		world.setBlock(i + 8, j + 3, k + 1, null, 0, k);
		world.setBlock(i + 8, j + 3, k + 2, null, 0, k);
		world.setBlock(i + 8, j + 3, k + 3, null, 0, k);
		world.setBlock(i + 8, j + 3, k + 4, null, 0, k);
		world.setBlock(i + 8, j + 3, k + 5, null, 0, k);
		world.setBlock(i + 8, j + 3, k + 6, null, 0, k);
		world.setBlock(i + 8, j + 3, k + 7, null, 0, k);
		world.setBlock(i + 8, j + 3, k + 8, null, 0, k);
		world.setBlock(i + 8, j + 3, k + 9, null, 0, k);
		world.setBlock(i + 8, j + 3, k + 10, null, 0, k);
		world.setBlock(i + 8, j + 3, k + 11, null, 0, k);
		world.setBlock(i + 8, j + 3, k + 12, null, 0, k);
		world.setBlock(i + 8, j + 4, k + 0, null, 0, k);
		world.setBlock(i + 8, j + 4, k + 1, null, 0, k);
		world.setBlock(i + 8, j + 4, k + 2, null, 0, k);
		world.setBlock(i + 8, j + 4, k + 3, null, 0, k);
		world.setBlock(i + 8, j + 4, k + 4, null, 0, k);
		world.setBlock(i + 8, j + 4, k + 5, null, 0, k);
		world.setBlock(i + 8, j + 4, k + 6, null, 0, k);
		world.setBlock(i + 8, j + 4, k + 7, null, 0, k);
		world.setBlock(i + 8, j + 4, k + 8, null, 0, k);
		world.setBlock(i + 8, j + 4, k + 9, null, 0, k);
		world.setBlock(i + 8, j + 4, k + 10, null, 0, k);
		world.setBlock(i + 8, j + 4, k + 11, null, 0, k);
		world.setBlock(i + 8, j + 4, k + 12, null, 0, k);
		world.setBlock(i + 9, j + 0, k + 0, Blocks.leaves);
		world.setBlock(i + 9, j + 0, k + 1, null, 0, k);
		world.setBlock(i + 9, j + 0, k + 2, null, 0, k);
		world.setBlock(i + 9, j + 0, k + 3, null, 0, k);
		world.setBlock(i + 9, j + 0, k + 4, null, 0, k);
		world.setBlock(i + 9, j + 0, k + 5, null, 0, k);
		world.setBlock(i + 9, j + 0, k + 6, null, 0, k);
		world.setBlock(i + 9, j + 0, k + 7, null, 0, k);
		world.setBlock(i + 9, j + 0, k + 8, null, 0, k);
		world.setBlock(i + 9, j + 0, k + 9, null, 0, k);
		world.setBlock(i + 9, j + 0, k + 10, null, 0, k);
		world.setBlock(i + 9, j + 0, k + 11, null, 0, k);
		world.setBlock(i + 9, j + 0, k + 12, Blocks.leaves);
		world.setBlock(i + 9, j + 1, k + 0, Blocks.leaves);
		world.setBlock(i + 9, j + 1, k + 1, null, 0, k);
		world.setBlock(i + 9, j + 1, k + 2, null, 0, k);
		world.setBlock(i + 9, j + 1, k + 3, null, 0, k);
		world.setBlock(i + 9, j + 1, k + 4, null, 0, k);
		world.setBlock(i + 9, j + 1, k + 5, null, 0, k);
		world.setBlock(i + 9, j + 1, k + 6, null, 0, k);
		world.setBlock(i + 9, j + 1, k + 7, null, 0, k);
		world.setBlock(i + 9, j + 1, k + 8, null, 0, k);
		world.setBlock(i + 9, j + 1, k + 9, null, 0, k);
		world.setBlock(i + 9, j + 1, k + 10, null, 0, k);
		world.setBlock(i + 9, j + 1, k + 11, null, 0, k);
		world.setBlock(i + 9, j + 1, k + 12, Blocks.leaves);
		world.setBlock(i + 9, j + 2, k + 0, Blocks.leaves);
		world.setBlock(i + 9, j + 2, k + 1, null, 0, k);
		world.setBlock(i + 9, j + 2, k + 2, null, 0, k);
		world.setBlock(i + 9, j + 2, k + 3, null, 0, k);
		world.setBlock(i + 9, j + 2, k + 4, null, 0, k);
		world.setBlock(i + 9, j + 2, k + 5, null, 0, k);
		world.setBlock(i + 9, j + 2, k + 6, null, 0, k);
		world.setBlock(i + 9, j + 2, k + 7, null, 0, k);
		world.setBlock(i + 9, j + 2, k + 8, null, 0, k);
		world.setBlock(i + 9, j + 2, k + 9, null, 0, k);
		world.setBlock(i + 9, j + 2, k + 10, null, 0, k);
		world.setBlock(i + 9, j + 2, k + 11, null, 0, k);
		world.setBlock(i + 9, j + 2, k + 12, Blocks.leaves);
		world.setBlock(i + 9, j + 3, k + 0, null, 0, k);
		world.setBlock(i + 9, j + 3, k + 1, null, 0, k);
		world.setBlock(i + 9, j + 3, k + 2, null, 0, k);
		world.setBlock(i + 9, j + 3, k + 3, null, 0, k);
		world.setBlock(i + 9, j + 3, k + 4, null, 0, k);
		world.setBlock(i + 9, j + 3, k + 5, null, 0, k);
		world.setBlock(i + 9, j + 3, k + 6, null, 0, k);
		world.setBlock(i + 9, j + 3, k + 7, null, 0, k);
		world.setBlock(i + 9, j + 3, k + 8, null, 0, k);
		world.setBlock(i + 9, j + 3, k + 9, null, 0, k);
		world.setBlock(i + 9, j + 3, k + 10, null, 0, k);
		world.setBlock(i + 9, j + 3, k + 11, null, 0, k);
		world.setBlock(i + 9, j + 3, k + 12, null, 0, k);
		world.setBlock(i + 9, j + 4, k + 0, null, 0, k);
		world.setBlock(i + 9, j + 4, k + 1, null, 0, k);
		world.setBlock(i + 9, j + 4, k + 2, null, 0, k);
		world.setBlock(i + 9, j + 4, k + 3, null, 0, k);
		world.setBlock(i + 9, j + 4, k + 4, null, 0, k);
		world.setBlock(i + 9, j + 4, k + 5, null, 0, k);
		world.setBlock(i + 9, j + 4, k + 6, null, 0, k);
		world.setBlock(i + 9, j + 4, k + 7, null, 0, k);
		world.setBlock(i + 9, j + 4, k + 8, null, 0, k);
		world.setBlock(i + 9, j + 4, k + 9, null, 0, k);
		world.setBlock(i + 9, j + 4, k + 10, null, 0, k);
		world.setBlock(i + 9, j + 4, k + 11, null, 0, k);
		world.setBlock(i + 9, j + 4, k + 12, null, 0, k);
		world.setBlock(i + 10, j + 0, k + 0, Blocks.leaves);
		world.setBlock(i + 10, j + 0, k + 1, null, 0, k);
		world.setBlock(i + 10, j + 0, k + 2, null, 0, k);
		world.setBlock(i + 10, j + 0, k + 3, Blocks.planks);
		world.setBlock(i + 10, j + 0, k + 4, Blocks.planks);
		world.setBlock(i + 10, j + 0, k + 5, Blocks.planks);
		world.setBlock(i + 10, j + 0, k + 6, Blocks.planks);
		world.setBlock(i + 10, j + 0, k + 7, Blocks.planks);
		world.setBlock(i + 10, j + 0, k + 8, Blocks.planks);
		world.setBlock(i + 10, j + 0, k + 9, Blocks.planks);
		world.setBlock(i + 10, j + 0, k + 10, null, 0, k);
		world.setBlock(i + 10, j + 0, k + 11, null, 0, k);
		world.setBlock(i + 10, j + 0, k + 12, Blocks.leaves);
		world.setBlock(i + 10, j + 1, k + 0, Blocks.leaves);
		world.setBlock(i + 10, j + 1, k + 1, null, 0, k);
		world.setBlock(i + 10, j + 1, k + 2, null, 0, k);
		world.setBlock(i + 10, j + 1, k + 3, Blocks.planks);
		world.setBlock(i + 10, j + 1, k + 4, Blocks.planks);
		world.setBlock(i + 10, j + 1, k + 5, Blocks.planks);
		world.setBlock(i + 10, j + 1, k + 6, Blocks.planks);
		world.setBlock(i + 10, j + 1, k + 7, Blocks.planks);
		world.setBlock(i + 10, j + 1, k + 8, Blocks.planks);
		world.setBlock(i + 10, j + 1, k + 9, Blocks.planks);
		world.setBlock(i + 10, j + 1, k + 10, null, 0, k);
		world.setBlock(i + 10, j + 1, k + 11, null, 0, k);
		world.setBlock(i + 10, j + 1, k + 12, Blocks.leaves);
		world.setBlock(i + 10, j + 2, k + 0, Blocks.leaves);
		world.setBlock(i + 10, j + 2, k + 1, null, 0, k);
		world.setBlock(i + 10, j + 2, k + 2, null, 0, k);
		world.setBlock(i + 10, j + 2, k + 3, Blocks.glass);
		world.setBlock(i + 10, j + 2, k + 4, Blocks.glass);
		world.setBlock(i + 10, j + 2, k + 5, Blocks.glass);
		world.setBlock(i + 10, j + 2, k + 6, Blocks.glass);
		world.setBlock(i + 10, j + 2, k + 7, Blocks.glass);
		world.setBlock(i + 10, j + 2, k + 8, Blocks.glass);
		world.setBlock(i + 10, j + 2, k + 9, Blocks.glass);
		world.setBlock(i + 10, j + 2, k + 10, null, 0, k);
		world.setBlock(i + 10, j + 2, k + 11, null, 0, k);
		world.setBlock(i + 10, j + 2, k + 12, Blocks.leaves);
		world.setBlock(i + 10, j + 3, k + 0, null, 0, k);
		world.setBlock(i + 10, j + 3, k + 1, null, 0, k);
		world.setBlock(i + 10, j + 3, k + 2, null, 0, k);
		world.setBlock(i + 10, j + 3, k + 3, Blocks.planks);
		world.setBlock(i + 10, j + 3, k + 4, Blocks.planks);
		world.setBlock(i + 10, j + 3, k + 5, Blocks.planks);
		world.setBlock(i + 10, j + 3, k + 6, Blocks.planks);
		world.setBlock(i + 10, j + 3, k + 7, Blocks.planks);
		world.setBlock(i + 10, j + 3, k + 8, Blocks.planks);
		world.setBlock(i + 10, j + 3, k + 9, Blocks.planks);
		world.setBlock(i + 10, j + 3, k + 10, null, 0, k);
		world.setBlock(i + 10, j + 3, k + 11, null, 0, k);
		world.setBlock(i + 10, j + 3, k + 12, null, 0, k);
		world.setBlock(i + 10, j + 4, k + 0, null, 0, k);
		world.setBlock(i + 10, j + 4, k + 1, null, 0, k);
		world.setBlock(i + 10, j + 4, k + 2, null, 0, k);
		world.setBlock(i + 10, j + 4, k + 3, null, 0, k);
		world.setBlock(i + 10, j + 4, k + 4, null, 0, k);
		world.setBlock(i + 10, j + 4, k + 5, null, 0, k);
		world.setBlock(i + 10, j + 4, k + 6, null, 0, k);
		world.setBlock(i + 10, j + 4, k + 7, null, 0, k);
		world.setBlock(i + 10, j + 4, k + 8, null, 0, k);
		world.setBlock(i + 10, j + 4, k + 9, null, 0, k);
		world.setBlock(i + 10, j + 4, k + 10, null, 0, k);
		world.setBlock(i + 10, j + 4, k + 11, null, 0, k);
		world.setBlock(i + 10, j + 4, k + 12, null, 0, k);
		world.setBlock(i + 11, j + 0, k + 0, Blocks.leaves);
		world.setBlock(i + 11, j + 0, k + 1, null, 0, k);
		world.setBlock(i + 11, j + 0, k + 2, null, 0, k);
		world.setBlock(i + 11, j + 0, k + 3, Blocks.planks);
		world.setBlock(i + 11, j + 0, k + 4, Blocks.planks);
		world.setBlock(i + 11, j + 0, k + 5, Blocks.planks);
		world.setBlock(i + 11, j + 0, k + 6, Blocks.wool);
		world.setBlock(i + 11, j + 0, k + 7, Blocks.planks);
		world.setBlock(i + 11, j + 0, k + 8, Blocks.planks);
		world.setBlock(i + 11, j + 0, k + 9, Blocks.planks);
		world.setBlock(i + 11, j + 0, k + 10, null, 0, k);
		world.setBlock(i + 11, j + 0, k + 11, null, 0, k);
		world.setBlock(i + 11, j + 0, k + 12, Blocks.leaves);
		world.setBlock(i + 11, j + 1, k + 0, Blocks.leaves);
		world.setBlock(i + 11, j + 1, k + 1, null, 0, k);
		world.setBlock(i + 11, j + 1, k + 2, null, 0, k);
		world.setBlock(i + 11, j + 1, k + 3, Blocks.planks);
		world.setBlock(i + 11, j + 1, k + 4, Blocks.chest);
		world.setBlock(i + 11, j + 1, k + 5, Blocks.chest);
		world.setBlock(i + 11, j + 1, k + 6, Blocks.bed, 0, 0);
		world.setBlock(i + 11, j + 1, k + 7, Blocks.chest);
		world.setBlock(i + 11, j + 1, k + 8, Blocks.chest);
		world.setBlock(i + 11, j + 1, k + 9, Blocks.planks);
		world.setBlock(i + 11, j + 1, k + 10, null, 0, k);
		world.setBlock(i + 11, j + 1, k + 11, null, 0, k);
		world.setBlock(i + 11, j + 1, k + 12, Blocks.leaves);
		world.setBlock(i + 11, j + 2, k + 0, Blocks.leaves);
		world.setBlock(i + 11, j + 2, k + 1, null, 0, k);
		world.setBlock(i + 11, j + 2, k + 2, null, 0, k);
		world.setBlock(i + 11, j + 2, k + 3, Blocks.glass);
		world.setBlock(i + 11, j + 2, k + 4, null, 0, k);
		world.setBlock(i + 11, j + 2, k + 5, null, 0, k);
		world.setBlock(i + 11, j + 2, k + 6, null, 0, k);
		world.setBlock(i + 11, j + 2, k + 7, null, 0, k);
		world.setBlock(i + 11, j + 2, k + 8, null, 0, k);
		world.setBlock(i + 11, j + 2, k + 9, Blocks.glass);
		world.setBlock(i + 11, j + 2, k + 10, null, 0, k);
		world.setBlock(i + 11, j + 2, k + 11, null, 0, k);
		world.setBlock(i + 11, j + 2, k + 12, Blocks.leaves);
		world.setBlock(i + 11, j + 3, k + 0, null, 0, k);
		world.setBlock(i + 11, j + 3, k + 1, null, 0, k);
		world.setBlock(i + 11, j + 3, k + 2, null, 0, k);
		world.setBlock(i + 11, j + 3, k + 3, Blocks.planks);
		world.setBlock(i + 11, j + 3, k + 4, null, 0, k);
		world.setBlock(i + 11, j + 3, k + 5, null, 0, k);
		world.setBlock(i + 11, j + 3, k + 6, null, 0, k);
		world.setBlock(i + 11, j + 3, k + 7, null, 0, k);
		world.setBlock(i + 11, j + 3, k + 8, null, 0, k);
		world.setBlock(i + 11, j + 3, k + 9, Blocks.planks);
		world.setBlock(i + 11, j + 3, k + 10, null, 0, k);
		world.setBlock(i + 11, j + 3, k + 11, null, 0, k);
		world.setBlock(i + 11, j + 3, k + 12, null, 0, k);
		world.setBlock(i + 11, j + 4, k + 0, null, 0, k);
		world.setBlock(i + 11, j + 4, k + 1, null, 0, k);
		world.setBlock(i + 11, j + 4, k + 2, null, 0, k);
		world.setBlock(i + 11, j + 4, k + 3, null, 0, k);
		world.setBlock(i + 11, j + 4, k + 4, Blocks.planks);
		world.setBlock(i + 11, j + 4, k + 5, Blocks.planks);
		world.setBlock(i + 11, j + 4, k + 6, Blocks.planks);
		world.setBlock(i + 11, j + 4, k + 7, Blocks.planks);
		world.setBlock(i + 11, j + 4, k + 8, Blocks.planks);
		world.setBlock(i + 11, j + 4, k + 9, null, 0, k);
		world.setBlock(i + 11, j + 4, k + 10, null, 0, k);
		world.setBlock(i + 11, j + 4, k + 11, null, 0, k);
		world.setBlock(i + 11, j + 4, k + 12, null, 0, k);
		world.setBlock(i + 12, j + 0, k + 0, Blocks.leaves);
		world.setBlock(i + 12, j + 0, k + 1, null, 0, k);
		world.setBlock(i + 12, j + 0, k + 2, null, 0, k);
		world.setBlock(i + 12, j + 0, k + 3, Blocks.planks);
		world.setBlock(i + 12, j + 0, k + 4, Blocks.planks);
		world.setBlock(i + 12, j + 0, k + 5, Blocks.wool);
		world.setBlock(i + 12, j + 0, k + 6, Blocks.wool);
		world.setBlock(i + 12, j + 0, k + 7, Blocks.wool);
		world.setBlock(i + 12, j + 0, k + 8, Blocks.planks);
		world.setBlock(i + 12, j + 0, k + 9, Blocks.planks);
		world.setBlock(i + 12, j + 0, k + 10, null, 0, k);
		world.setBlock(i + 12, j + 0, k + 11, null, 0, k);
		world.setBlock(i + 12, j + 0, k + 12, Blocks.leaves);
		world.setBlock(i + 12, j + 1, k + 0, Blocks.leaves);
		world.setBlock(i + 12, j + 1, k + 1, null, 0, k);
		world.setBlock(i + 12, j + 1, k + 2, null, 0, k);
		world.setBlock(i + 12, j + 1, k + 3, Blocks.planks);
		world.setBlock(i + 12, j + 1, k + 4, null, 0, k);
		world.setBlock(i + 12, j + 1, k + 5, null, 0, k);
		world.setBlock(i + 12, j + 1, k + 6, Blocks.bed);
		world.setBlock(i + 12, j + 1, k + 7, null, 0, k);
		world.setBlock(i + 12, j + 1, k + 8, null, 0, k);
		world.setBlock(i + 12, j + 1, k + 9, Blocks.planks);
		world.setBlock(i + 12, j + 1, k + 10, null, 0, k);
		world.setBlock(i + 12, j + 1, k + 11, null, 0, k);
		world.setBlock(i + 12, j + 1, k + 12, Blocks.leaves);
		world.setBlock(i + 12, j + 2, k + 0, Blocks.leaves);
		world.setBlock(i + 12, j + 2, k + 1, null, 0, k);
		world.setBlock(i + 12, j + 2, k + 2, null, 0, k);
		world.setBlock(i + 12, j + 2, k + 3, Blocks.glass);
		world.setBlock(i + 12, j + 2, k + 4, null, 0, k);
		world.setBlock(i + 12, j + 2, k + 5, null, 0, k);
		world.setBlock(i + 12, j + 2, k + 6, null, 0, k);
		world.setBlock(i + 12, j + 2, k + 7, null, 0, k);
		world.setBlock(i + 12, j + 2, k + 8, null, 0, k);
		world.setBlock(i + 12, j + 2, k + 9, Blocks.glass);
		world.setBlock(i + 12, j + 2, k + 10, null, 0, k);
		world.setBlock(i + 12, j + 2, k + 11, null, 0, k);
		world.setBlock(i + 12, j + 2, k + 12, Blocks.leaves);
		world.setBlock(i + 12, j + 3, k + 0, null, 0, k);
		world.setBlock(i + 12, j + 3, k + 1, null, 0, k);
		world.setBlock(i + 12, j + 3, k + 2, null, 0, k);
		world.setBlock(i + 12, j + 3, k + 3, Blocks.planks);
		world.setBlock(i + 12, j + 3, k + 4, null, 0, k);
		world.setBlock(i + 12, j + 3, k + 5, null, 0, k);
		world.setBlock(i + 12, j + 3, k + 6, null, 0, k);
		world.setBlock(i + 12, j + 3, k + 7, null, 0, k);
		world.setBlock(i + 12, j + 3, k + 8, null, 0, k);
		world.setBlock(i + 12, j + 3, k + 9, Blocks.planks);
		world.setBlock(i + 12, j + 3, k + 10, null, 0, k);
		world.setBlock(i + 12, j + 3, k + 11, null, 0, k);
		world.setBlock(i + 12, j + 3, k + 12, null, 0, k);
		world.setBlock(i + 12, j + 4, k + 0, null, 0, k);
		world.setBlock(i + 12, j + 4, k + 1, null, 0, k);
		world.setBlock(i + 12, j + 4, k + 2, null, 0, k);
		world.setBlock(i + 12, j + 4, k + 3, null, 0, k);
		world.setBlock(i + 12, j + 4, k + 4, Blocks.planks);
		world.setBlock(i + 12, j + 4, k + 5, Blocks.glass);
		world.setBlock(i + 12, j + 4, k + 6, Blocks.glass);
		world.setBlock(i + 12, j + 4, k + 7, Blocks.glass);
		world.setBlock(i + 12, j + 4, k + 8, Blocks.planks);
		world.setBlock(i + 12, j + 4, k + 9, null, 0, k);
		world.setBlock(i + 12, j + 4, k + 10, null, 0, k);
		world.setBlock(i + 12, j + 4, k + 11, null, 0, k);
		world.setBlock(i + 12, j + 4, k + 12, null, 0, k);
		world.setBlock(i + 13, j + 0, k + 0, Blocks.leaves);
		world.setBlock(i + 13, j + 0, k + 1, null, 0, k);
		world.setBlock(i + 13, j + 0, k + 2, null, 0, k);
		world.setBlock(i + 13, j + 0, k + 3, Blocks.planks);
		world.setBlock(i + 13, j + 0, k + 4, Blocks.wool);
		world.setBlock(i + 13, j + 0, k + 5, Blocks.wool);
		world.setBlock(i + 13, j + 0, k + 6, Blocks.glowstone);
		world.setBlock(i + 13, j + 0, k + 7, Blocks.wool);
		world.setBlock(i + 13, j + 0, k + 8, Blocks.wool);
		world.setBlock(i + 13, j + 0, k + 9, Blocks.planks);
		world.setBlock(i + 13, j + 0, k + 10, null, 0, k);
		world.setBlock(i + 13, j + 0, k + 11, null, 0, k);
		world.setBlock(i + 13, j + 0, k + 12, Blocks.leaves);
		world.setBlock(i + 13, j + 1, k + 0, Blocks.leaves);
		world.setBlock(i + 13, j + 1, k + 1, null, 0, k);
		world.setBlock(i + 13, j + 1, k + 2, null, 0, k);
		world.setBlock(i + 13, j + 1, k + 3, Blocks.planks);
		world.setBlock(i + 13, j + 1, k + 4, null, 0, k);
		world.setBlock(i + 13, j + 1, k + 5, null, 0, k);
		world.setBlock(i + 13, j + 1, k + 6, null, 0, k);
		world.setBlock(i + 13, j + 1, k + 7, null, 0, k);
		world.setBlock(i + 13, j + 1, k + 8, null, 0, k);
		world.setBlock(i + 13, j + 1, k + 9, Blocks.planks);
		world.setBlock(i + 13, j + 1, k + 10, null, 0, k);
		world.setBlock(i + 13, j + 1, k + 11, null, 0, k);
		world.setBlock(i + 13, j + 1, k + 12, Blocks.leaves);
		world.setBlock(i + 13, j + 2, k + 0, Blocks.leaves);
		world.setBlock(i + 13, j + 2, k + 1, null, 0, k);
		world.setBlock(i + 13, j + 2, k + 2, null, 0, k);
		world.setBlock(i + 13, j + 2, k + 3, Blocks.glass);
		world.setBlock(i + 13, j + 2, k + 4, null, 0, k);
		world.setBlock(i + 13, j + 2, k + 5, null, 0, k);
		world.setBlock(i + 13, j + 2, k + 6, null, 0, k);
		world.setBlock(i + 13, j + 2, k + 7, null, 0, k);
		world.setBlock(i + 13, j + 2, k + 8, null, 0, k);
		world.setBlock(i + 13, j + 2, k + 9, Blocks.glass);
		world.setBlock(i + 13, j + 2, k + 10, null, 0, k);
		world.setBlock(i + 13, j + 2, k + 11, null, 0, k);
		world.setBlock(i + 13, j + 2, k + 12, Blocks.leaves);
		world.setBlock(i + 13, j + 3, k + 0, null, 0, k);
		world.setBlock(i + 13, j + 3, k + 1, null, 0, k);
		world.setBlock(i + 13, j + 3, k + 2, null, 0, k);
		world.setBlock(i + 13, j + 3, k + 3, Blocks.planks);
		world.setBlock(i + 13, j + 3, k + 4, null, 0, k);
		world.setBlock(i + 13, j + 3, k + 5, null, 0, k);
		world.setBlock(i + 13, j + 3, k + 6, null, 0, k);
		world.setBlock(i + 13, j + 3, k + 7, null, 0, k);
		world.setBlock(i + 13, j + 3, k + 8, null, 0, k);
		world.setBlock(i + 13, j + 3, k + 9, Blocks.planks);
		world.setBlock(i + 13, j + 3, k + 10, null, 0, k);
		world.setBlock(i + 13, j + 3, k + 11, null, 0, k);
		world.setBlock(i + 13, j + 3, k + 12, null, 0, k);
		world.setBlock(i + 13, j + 4, k + 0, null, 0, k);
		world.setBlock(i + 13, j + 4, k + 1, null, 0, k);
		world.setBlock(i + 13, j + 4, k + 2, null, 0, k);
		world.setBlock(i + 13, j + 4, k + 3, null, 0, k);
		world.setBlock(i + 13, j + 4, k + 4, Blocks.planks);
		world.setBlock(i + 13, j + 4, k + 5, Blocks.glass);
		world.setBlock(i + 13, j + 4, k + 6, Blocks.diamond_block);
		world.setBlock(i + 13, j + 4, k + 7, Blocks.glass);
		world.setBlock(i + 13, j + 4, k + 8, Blocks.planks);
		world.setBlock(i + 13, j + 4, k + 9, null, 0, k);
		world.setBlock(i + 13, j + 4, k + 10, null, 0, k);
		world.setBlock(i + 13, j + 4, k + 11, null, 0, k);
		world.setBlock(i + 13, j + 4, k + 12, null, 0, k);
		world.setBlock(i + 14, j + 0, k + 0, Blocks.leaves);
		world.setBlock(i + 14, j + 0, k + 1, null, 0, k);
		world.setBlock(i + 14, j + 0, k + 2, null, 0, k);
		world.setBlock(i + 14, j + 0, k + 3, Blocks.planks);
		world.setBlock(i + 14, j + 0, k + 4, Blocks.planks);
		world.setBlock(i + 14, j + 0, k + 5, Blocks.wool);
		world.setBlock(i + 14, j + 0, k + 6, Blocks.wool);
		world.setBlock(i + 14, j + 0, k + 7, Blocks.wool);
		world.setBlock(i + 14, j + 0, k + 8, Blocks.planks);
		world.setBlock(i + 14, j + 0, k + 9, Blocks.planks);
		world.setBlock(i + 14, j + 0, k + 10, null, 0, k);
		world.setBlock(i + 14, j + 0, k + 11, null, 0, k);
		world.setBlock(i + 14, j + 0, k + 12, Blocks.leaves);
		world.setBlock(i + 14, j + 1, k + 0, Blocks.leaves);
		world.setBlock(i + 14, j + 1, k + 1, null, 0, k);
		world.setBlock(i + 14, j + 1, k + 2, null, 0, k);
		world.setBlock(i + 14, j + 1, k + 3, Blocks.planks);
		world.setBlock(i + 14, j + 1, k + 4, Blocks.wooden_slab);
		world.setBlock(i + 14, j + 1, k + 5, Blocks.fence);
		world.setBlock(i + 14, j + 1, k + 6, null, 0, k);
		world.setBlock(i + 14, j + 1, k + 7, null, 0, k);
		world.setBlock(i + 14, j + 1, k + 8, Blocks.furnace);
		world.setBlock(i + 14, j + 1, k + 9, Blocks.planks);
		world.setBlock(i + 14, j + 1, k + 10, null, 0, k);
		world.setBlock(i + 14, j + 1, k + 11, null, 0, k);
		world.setBlock(i + 14, j + 1, k + 12, Blocks.leaves);
		world.setBlock(i + 14, j + 2, k + 0, Blocks.leaves);
		world.setBlock(i + 14, j + 2, k + 1, null, 0, k);
		world.setBlock(i + 14, j + 2, k + 2, null, 0, k);
		world.setBlock(i + 14, j + 2, k + 3, Blocks.glass);
		world.setBlock(i + 14, j + 2, k + 4, null, 0, k);
		world.setBlock(i + 14, j + 2, k + 6, null, 0, k);
		world.setBlock(i + 14, j + 2, k + 7, null, 0, k);
		world.setBlock(i + 14, j + 2, k + 8, null, 0, k);
		world.setBlock(i + 14, j + 2, k + 9, Blocks.glass);
		world.setBlock(i + 14, j + 2, k + 10, null, 0, k);
		world.setBlock(i + 14, j + 2, k + 11, null, 0, k);
		world.setBlock(i + 14, j + 2, k + 12, Blocks.leaves);
		world.setBlock(i + 14, j + 3, k + 0, null, 0, k);
		world.setBlock(i + 14, j + 3, k + 1, null, 0, k);
		world.setBlock(i + 14, j + 3, k + 2, null, 0, k);
		world.setBlock(i + 14, j + 3, k + 3, Blocks.planks);
		world.setBlock(i + 14, j + 3, k + 4, null, 0, k);
		world.setBlock(i + 14, j + 3, k + 5, null, 0, k);
		world.setBlock(i + 14, j + 3, k + 6, null, 0, k);
		world.setBlock(i + 14, j + 3, k + 7, null, 0, k);
		world.setBlock(i + 14, j + 3, k + 8, null, 0, k);
		world.setBlock(i + 14, j + 3, k + 9, Blocks.planks);
		world.setBlock(i + 14, j + 3, k + 10, null, 0, k);
		world.setBlock(i + 14, j + 3, k + 11, null, 0, k);
		world.setBlock(i + 14, j + 3, k + 12, null, 0, k);
		world.setBlock(i + 14, j + 4, k + 0, null, 0, k);
		world.setBlock(i + 14, j + 4, k + 1, null, 0, k);
		world.setBlock(i + 14, j + 4, k + 2, null, 0, k);
		world.setBlock(i + 14, j + 4, k + 3, null, 0, k);
		world.setBlock(i + 14, j + 4, k + 4, Blocks.planks);
		world.setBlock(i + 14, j + 4, k + 5, Blocks.glass);
		world.setBlock(i + 14, j + 4, k + 6, Blocks.glass);
		world.setBlock(i + 14, j + 4, k + 7, Blocks.glass);
		world.setBlock(i + 14, j + 4, k + 8, Blocks.planks);
		world.setBlock(i + 14, j + 4, k + 9, null, 0, k);
		world.setBlock(i + 14, j + 4, k + 10, null, 0, k);
		world.setBlock(i + 14, j + 4, k + 11, null, 0, k);
		world.setBlock(i + 14, j + 4, k + 12, null, 0, k);
		world.setBlock(i + 15, j + 0, k + 0, Blocks.leaves);
		world.setBlock(i + 15, j + 0, k + 1, null, 0, k);
		world.setBlock(i + 15, j + 0, k + 2, null, 0, k);
		world.setBlock(i + 15, j + 0, k + 3, Blocks.planks);
		world.setBlock(i + 15, j + 0, k + 4, Blocks.planks);
		world.setBlock(i + 15, j + 0, k + 5, Blocks.planks);
		world.setBlock(i + 15, j + 0, k + 6, Blocks.wool);
		world.setBlock(i + 15, j + 0, k + 7, Blocks.planks);
		world.setBlock(i + 15, j + 0, k + 8, Blocks.planks);
		world.setBlock(i + 15, j + 0, k + 9, Blocks.planks);
		world.setBlock(i + 15, j + 0, k + 10, null, 0, k);
		world.setBlock(i + 15, j + 0, k + 11, null, 0, k);
		world.setBlock(i + 15, j + 0, k + 12, Blocks.leaves);
		world.setBlock(i + 15, j + 1, k + 0, Blocks.leaves);
		world.setBlock(i + 15, j + 1, k + 1, null, 0, k);
		world.setBlock(i + 15, j + 1, k + 2, null, 0, k);
		world.setBlock(i + 15, j + 1, k + 3, Blocks.planks);
		world.setBlock(i + 15, j + 1, k + 4, Blocks.wooden_slab);
		world.setBlock(i + 15, j + 1, k + 5, Blocks.wooden_slab);
		world.setBlock(i + 15, j + 1, k + 6, null, 0, k);
		world.setBlock(i + 15, j + 1, k + 7, Blocks.furnace);
		world.setBlock(i + 15, j + 1, k + 8, Blocks.furnace);
		world.setBlock(i + 15, j + 1, k + 9, Blocks.planks);
		world.setBlock(i + 15, j + 1, k + 10, null, 0, k);
		world.setBlock(i + 15, j + 1, k + 11, null, 0, k);
		world.setBlock(i + 15, j + 1, k + 12, Blocks.leaves);
		world.setBlock(i + 15, j + 2, k + 0, Blocks.leaves);
		world.setBlock(i + 15, j + 2, k + 1, null, 0, k);
		world.setBlock(i + 15, j + 2, k + 2, null, 0, k);
		world.setBlock(i + 15, j + 2, k + 3, Blocks.glass);
		world.setBlock(i + 15, j + 2, k + 4, null, 0, k);
		world.setBlock(i + 15, j + 2, k + 5, null, 0, k);
		world.setBlock(i + 15, j + 2, k + 6, null, 0, k);
		world.setBlock(i + 15, j + 2, k + 7, null, 0, k);
		world.setBlock(i + 15, j + 2, k + 8, null, 0, k);
		world.setBlock(i + 15, j + 2, k + 9, Blocks.glass);
		world.setBlock(i + 15, j + 2, k + 10, null, 0, k);
		world.setBlock(i + 15, j + 2, k + 11, null, 0, k);
		world.setBlock(i + 15, j + 2, k + 12, Blocks.leaves);
		world.setBlock(i + 15, j + 3, k + 0, null, 0, k);
		world.setBlock(i + 15, j + 3, k + 1, null, 0, k);
		world.setBlock(i + 15, j + 3, k + 2, null, 0, k);
		world.setBlock(i + 15, j + 3, k + 3, Blocks.planks);
		world.setBlock(i + 15, j + 3, k + 4, null, 0, k);
		world.setBlock(i + 15, j + 3, k + 5, null, 0, k);
		world.setBlock(i + 15, j + 3, k + 6, null, 0, k);
		world.setBlock(i + 15, j + 3, k + 7, null, 0, k);
		world.setBlock(i + 15, j + 3, k + 8, null, 0, k);
		world.setBlock(i + 15, j + 3, k + 9, Blocks.planks);
		world.setBlock(i + 15, j + 3, k + 10, null, 0, k);
		world.setBlock(i + 15, j + 3, k + 11, null, 0, k);
		world.setBlock(i + 15, j + 3, k + 12, null, 0, k);
		world.setBlock(i + 15, j + 4, k + 0, null, 0, k);
		world.setBlock(i + 15, j + 4, k + 1, null, 0, k);
		world.setBlock(i + 15, j + 4, k + 2, null, 0, k);
		world.setBlock(i + 15, j + 4, k + 3, null, 0, k);
		world.setBlock(i + 15, j + 4, k + 4, Blocks.planks);
		world.setBlock(i + 15, j + 4, k + 5, Blocks.planks);
		world.setBlock(i + 15, j + 4, k + 6, Blocks.planks);
		world.setBlock(i + 15, j + 4, k + 7, Blocks.planks);
		world.setBlock(i + 15, j + 4, k + 8, Blocks.planks);
		world.setBlock(i + 15, j + 4, k + 9, null, 0, k);
		world.setBlock(i + 15, j + 4, k + 10, null, 0, k);
		world.setBlock(i + 15, j + 4, k + 11, null, 0, k);
		world.setBlock(i + 15, j + 4, k + 12, null, 0, k);
		world.setBlock(i + 16, j + 0, k + 0, Blocks.leaves);
		world.setBlock(i + 16, j + 0, k + 1, null, 0, k);
		world.setBlock(i + 16, j + 0, k + 2, null, 0, k);
		world.setBlock(i + 16, j + 0, k + 3, Blocks.planks);
		world.setBlock(i + 16, j + 0, k + 4, Blocks.planks);
		world.setBlock(i + 16, j + 0, k + 5, Blocks.planks);
		world.setBlock(i + 16, j + 0, k + 6, Blocks.planks);
		world.setBlock(i + 16, j + 0, k + 7, Blocks.planks);
		world.setBlock(i + 16, j + 0, k + 8, Blocks.planks);
		world.setBlock(i + 16, j + 0, k + 9, Blocks.planks);
		world.setBlock(i + 16, j + 0, k + 10, null, 0, k);
		world.setBlock(i + 16, j + 0, k + 11, null, 0, k);
		world.setBlock(i + 16, j + 0, k + 12, Blocks.leaves);
		world.setBlock(i + 16, j + 1, k + 0, Blocks.leaves);
		world.setBlock(i + 16, j + 1, k + 1, null, 0, k);
		world.setBlock(i + 16, j + 1, k + 2, null, 0, k);
		world.setBlock(i + 16, j + 1, k + 3, Blocks.planks);
		world.setBlock(i + 16, j + 1, k + 4, Blocks.planks);
		world.setBlock(i + 16, j + 1, k + 5, Blocks.planks);
		world.setBlock(i + 16, j + 1, k + 7, Blocks.planks);
		world.setBlock(i + 16, j + 1, k + 8, Blocks.planks);
		world.setBlock(i + 16, j + 1, k + 9, Blocks.planks);
		world.setBlock(i + 16, j + 1, k + 10, null, 0, k);
		world.setBlock(i + 16, j + 1, k + 11, null, 0, k);
		world.setBlock(i + 16, j + 1, k + 12, Blocks.leaves);
		world.setBlock(i + 16, j + 2, k + 0, Blocks.leaves);
		world.setBlock(i + 16, j + 2, k + 1, null, 0, k);
		world.setBlock(i + 16, j + 2, k + 2, null, 0, k);
		world.setBlock(i + 16, j + 2, k + 3, Blocks.glass);
		world.setBlock(i + 16, j + 2, k + 4, Blocks.glass);
		world.setBlock(i + 16, j + 2, k + 5, Blocks.glass);
		world.setBlock(i + 16, j + 2, k + 7, Blocks.glass);
		world.setBlock(i + 16, j + 2, k + 8, Blocks.glass);
		world.setBlock(i + 16, j + 2, k + 9, Blocks.glass);
		world.setBlock(i + 16, j + 2, k + 10, null, 0, k);
		world.setBlock(i + 16, j + 2, k + 11, null, 0, k);
		world.setBlock(i + 16, j + 2, k + 12, Blocks.leaves);
		world.setBlock(i + 16, j + 3, k + 0, null, 0, k);
		world.setBlock(i + 16, j + 3, k + 1, null, 0, k);
		world.setBlock(i + 16, j + 3, k + 2, null, 0, k);
		world.setBlock(i + 16, j + 3, k + 3, Blocks.planks);
		world.setBlock(i + 16, j + 3, k + 4, Blocks.planks);
		world.setBlock(i + 16, j + 3, k + 5, Blocks.planks);
		world.setBlock(i + 16, j + 3, k + 6, Blocks.wooden_slab);
		world.setBlock(i + 16, j + 3, k + 7, Blocks.planks);
		world.setBlock(i + 16, j + 3, k + 8, Blocks.planks);
		world.setBlock(i + 16, j + 3, k + 9, Blocks.planks);
		world.setBlock(i + 16, j + 3, k + 10, null, 0, k);
		world.setBlock(i + 16, j + 3, k + 11, null, 0, k);
		world.setBlock(i + 16, j + 3, k + 12, null, 0, k);
		world.setBlock(i + 16, j + 4, k + 0, null, 0, k);
		world.setBlock(i + 16, j + 4, k + 1, null, 0, k);
		world.setBlock(i + 16, j + 4, k + 2, null, 0, k);
		world.setBlock(i + 16, j + 4, k + 3, null, 0, k);
		world.setBlock(i + 16, j + 4, k + 4, null, 0, k);
		world.setBlock(i + 16, j + 4, k + 5, null, 0, k);
		world.setBlock(i + 16, j + 4, k + 6, null, 0, k);
		world.setBlock(i + 16, j + 4, k + 7, null, 0, k);
		world.setBlock(i + 16, j + 4, k + 8, null, 0, k);
		world.setBlock(i + 16, j + 4, k + 9, null, 0, k);
		world.setBlock(i + 16, j + 4, k + 10, null, 0, k);
		world.setBlock(i + 16, j + 4, k + 11, null, 0, k);
		world.setBlock(i + 16, j + 4, k + 12, null, 0, k);
		world.setBlock(i + 17, j + 0, k + 0, Blocks.leaves);
		world.setBlock(i + 17, j + 0, k + 1, null, 0, k);
		world.setBlock(i + 17, j + 0, k + 2, null, 0, k);
		world.setBlock(i + 17, j + 0, k + 3, null, 0, k);
		world.setBlock(i + 17, j + 0, k + 4, null, 0, k);
		world.setBlock(i + 17, j + 0, k + 5, Blocks.wooden_slab);
		world.setBlock(i + 17, j + 0, k + 6, Blocks.wooden_slab);
		world.setBlock(i + 17, j + 0, k + 7, Blocks.wooden_slab);
		world.setBlock(i + 17, j + 0, k + 8, null, 0, k);
		world.setBlock(i + 17, j + 0, k + 9, null, 0, k);
		world.setBlock(i + 17, j + 0, k + 10, null, 0, k);
		world.setBlock(i + 17, j + 0, k + 11, null, 0, k);
		world.setBlock(i + 17, j + 0, k + 12, Blocks.leaves);
		world.setBlock(i + 17, j + 1, k + 0, Blocks.leaves);
		world.setBlock(i + 17, j + 1, k + 1, null, 0, k);
		world.setBlock(i + 17, j + 1, k + 2, null, 0, k);
		world.setBlock(i + 17, j + 1, k + 3, null, 0, k);
		world.setBlock(i + 17, j + 1, k + 4, null, 0, k);
		world.setBlock(i + 17, j + 1, k + 5, null, 0, k);
		world.setBlock(i + 17, j + 1, k + 6, null, 0, k);
		world.setBlock(i + 17, j + 1, k + 7, null, 0, k);
		world.setBlock(i + 17, j + 1, k + 8, null, 0, k);
		world.setBlock(i + 17, j + 1, k + 9, null, 0, k);
		world.setBlock(i + 17, j + 1, k + 10, null, 0, k);
		world.setBlock(i + 17, j + 1, k + 11, null, 0, k);
		world.setBlock(i + 17, j + 1, k + 12, Blocks.leaves);
		world.setBlock(i + 17, j + 2, k + 0, Blocks.leaves);
		world.setBlock(i + 17, j + 2, k + 1, null, 0, k);
		world.setBlock(i + 17, j + 2, k + 2, null, 0, k);
		world.setBlock(i + 17, j + 2, k + 3, null, 0, k);
		world.setBlock(i + 17, j + 2, k + 4, null, 0, k);
		world.setBlock(i + 17, j + 2, k + 5, null, 0, k);
		world.setBlock(i + 17, j + 2, k + 6, null, 0, k);
		world.setBlock(i + 17, j + 2, k + 7, null, 0, k);
		world.setBlock(i + 17, j + 2, k + 8, null, 0, k);
		world.setBlock(i + 17, j + 2, k + 9, null, 0, k);
		world.setBlock(i + 17, j + 2, k + 10, null, 0, k);
		world.setBlock(i + 17, j + 2, k + 11, null, 0, k);
		world.setBlock(i + 17, j + 2, k + 12, Blocks.leaves);
		world.setBlock(i + 17, j + 3, k + 0, null, 0, k);
		world.setBlock(i + 17, j + 3, k + 1, null, 0, k);
		world.setBlock(i + 17, j + 3, k + 2, null, 0, k);
		world.setBlock(i + 17, j + 3, k + 3, null, 0, k);
		world.setBlock(i + 17, j + 3, k + 4, null, 0, k);
		world.setBlock(i + 17, j + 3, k + 5, null, 0, k);
		world.setBlock(i + 17, j + 3, k + 7, null, 0, k);
		world.setBlock(i + 17, j + 3, k + 8, null, 0, k);
		world.setBlock(i + 17, j + 3, k + 9, null, 0, k);
		world.setBlock(i + 17, j + 3, k + 10, null, 0, k);
		world.setBlock(i + 17, j + 3, k + 11, null, 0, k);
		world.setBlock(i + 17, j + 3, k + 12, null, 0, k);
		world.setBlock(i + 17, j + 4, k + 0, null, 0, k);
		world.setBlock(i + 17, j + 4, k + 1, null, 0, k);
		world.setBlock(i + 17, j + 4, k + 2, null, 0, k);
		world.setBlock(i + 17, j + 4, k + 3, null, 0, k);
		world.setBlock(i + 17, j + 4, k + 4, null, 0, k);
		world.setBlock(i + 17, j + 4, k + 5, null, 0, k);
		world.setBlock(i + 17, j + 4, k + 6, null, 0, k);
		world.setBlock(i + 17, j + 4, k + 7, null, 0, k);
		world.setBlock(i + 17, j + 4, k + 8, null, 0, k);
		world.setBlock(i + 17, j + 4, k + 9, null, 0, k);
		world.setBlock(i + 17, j + 4, k + 10, null, 0, k);
		world.setBlock(i + 17, j + 4, k + 11, null, 0, k);
		world.setBlock(i + 17, j + 4, k + 12, null, 0, k);
		world.setBlock(i + 18, j + 0, k + 0, Blocks.leaves);
		world.setBlock(i + 18, j + 0, k + 1, null, 0, k);
		world.setBlock(i + 18, j + 0, k + 2, null, 0, k);
		world.setBlock(i + 18, j + 0, k + 3, null, 0, k);
		world.setBlock(i + 18, j + 0, k + 4, null, 0, k);
		world.setBlock(i + 18, j + 0, k + 5, null, 0, k);
		world.setBlock(i + 18, j + 0, k + 6, null, 0, k);
		world.setBlock(i + 18, j + 0, k + 7, null, 0, k);
		world.setBlock(i + 18, j + 0, k + 8, null, 0, k);
		world.setBlock(i + 18, j + 0, k + 9, null, 0, k);
		world.setBlock(i + 18, j + 0, k + 10, null, 0, k);
		world.setBlock(i + 18, j + 0, k + 11, null, 0, k);
		world.setBlock(i + 18, j + 0, k + 12, Blocks.leaves);
		world.setBlock(i + 18, j + 1, k + 0, Blocks.leaves);
		world.setBlock(i + 18, j + 1, k + 1, null, 0, k);
		world.setBlock(i + 18, j + 1, k + 2, null, 0, k);
		world.setBlock(i + 18, j + 1, k + 3, null, 0, k);
		world.setBlock(i + 18, j + 1, k + 4, null, 0, k);
		world.setBlock(i + 18, j + 1, k + 5, null, 0, k);
		world.setBlock(i + 18, j + 1, k + 6, null, 0, k);
		world.setBlock(i + 18, j + 1, k + 7, null, 0, k);
		world.setBlock(i + 18, j + 1, k + 8, null, 0, k);
		world.setBlock(i + 18, j + 1, k + 9, null, 0, k);
		world.setBlock(i + 18, j + 1, k + 10, null, 0, k);
		world.setBlock(i + 18, j + 1, k + 11, null, 0, k);
		world.setBlock(i + 18, j + 1, k + 12, Blocks.leaves);
		world.setBlock(i + 18, j + 2, k + 0, Blocks.leaves);
		world.setBlock(i + 18, j + 2, k + 1, null, 0, k);
		world.setBlock(i + 18, j + 2, k + 2, null, 0, k);
		world.setBlock(i + 18, j + 2, k + 3, null, 0, k);
		world.setBlock(i + 18, j + 2, k + 4, null, 0, k);
		world.setBlock(i + 18, j + 2, k + 5, null, 0, k);
		world.setBlock(i + 18, j + 2, k + 6, null, 0, k);
		world.setBlock(i + 18, j + 2, k + 7, null, 0, k);
		world.setBlock(i + 18, j + 2, k + 8, null, 0, k);
		world.setBlock(i + 18, j + 2, k + 9, null, 0, k);
		world.setBlock(i + 18, j + 2, k + 10, null, 0, k);
		world.setBlock(i + 18, j + 2, k + 11, null, 0, k);
		world.setBlock(i + 18, j + 2, k + 12, Blocks.leaves);
		world.setBlock(i + 18, j + 3, k + 0, null, 0, k);
		world.setBlock(i + 18, j + 3, k + 1, null, 0, k);
		world.setBlock(i + 18, j + 3, k + 2, null, 0, k);
		world.setBlock(i + 18, j + 3, k + 3, null, 0, k);
		world.setBlock(i + 18, j + 3, k + 4, null, 0, k);
		world.setBlock(i + 18, j + 3, k + 5, null, 0, k);
		world.setBlock(i + 18, j + 3, k + 6, null, 0, k);
		world.setBlock(i + 18, j + 3, k + 7, null, 0, k);
		world.setBlock(i + 18, j + 3, k + 8, null, 0, k);
		world.setBlock(i + 18, j + 3, k + 9, null, 0, k);
		world.setBlock(i + 18, j + 3, k + 10, null, 0, k);
		world.setBlock(i + 18, j + 3, k + 11, null, 0, k);
		world.setBlock(i + 18, j + 3, k + 12, null, 0, k);
		world.setBlock(i + 18, j + 4, k + 0, null, 0, k);
		world.setBlock(i + 18, j + 4, k + 1, null, 0, k);
		world.setBlock(i + 18, j + 4, k + 2, null, 0, k);
		world.setBlock(i + 18, j + 4, k + 3, null, 0, k);
		world.setBlock(i + 18, j + 4, k + 4, null, 0, k);
		world.setBlock(i + 18, j + 4, k + 5, null, 0, k);
		world.setBlock(i + 18, j + 4, k + 6, null, 0, k);
		world.setBlock(i + 18, j + 4, k + 7, null, 0, k);
		world.setBlock(i + 18, j + 4, k + 8, null, 0, k);
		world.setBlock(i + 18, j + 4, k + 9, null, 0, k);
		world.setBlock(i + 18, j + 4, k + 10, null, 0, k);
		world.setBlock(i + 18, j + 4, k + 11, null, 0, k);
		world.setBlock(i + 18, j + 4, k + 12, null, 0, k);
		world.setBlock(i + 19, j + 0, k + 0, Blocks.leaves);
		world.setBlock(i + 19, j + 0, k + 1, Blocks.leaves);
		world.setBlock(i + 19, j + 0, k + 2, Blocks.leaves);
		world.setBlock(i + 19, j + 0, k + 3, Blocks.leaves);
		world.setBlock(i + 19, j + 0, k + 4, Blocks.leaves);
		world.setBlock(i + 19, j + 0, k + 5, null, 0, k);
		world.setBlock(i + 19, j + 0, k + 6, null, 0, k);
		world.setBlock(i + 19, j + 0, k + 7, null, 0, k);
		world.setBlock(i + 19, j + 0, k + 8, Blocks.leaves);
		world.setBlock(i + 19, j + 0, k + 9, Blocks.leaves);
		world.setBlock(i + 19, j + 0, k + 10, Blocks.leaves);
		world.setBlock(i + 19, j + 0, k + 11, Blocks.leaves);
		world.setBlock(i + 19, j + 0, k + 12, Blocks.leaves);
		world.setBlock(i + 19, j + 1, k + 0, Blocks.leaves);
		world.setBlock(i + 19, j + 1, k + 1, Blocks.leaves);
		world.setBlock(i + 19, j + 1, k + 2, Blocks.leaves);
		world.setBlock(i + 19, j + 1, k + 3, Blocks.leaves);
		world.setBlock(i + 19, j + 1, k + 4, Blocks.leaves);
		world.setBlock(i + 19, j + 1, k + 5, null, 0, k);
		world.setBlock(i + 19, j + 1, k + 6, null, 0, k);
		world.setBlock(i + 19, j + 1, k + 7, null, 0, k);
		world.setBlock(i + 19, j + 1, k + 8, Blocks.leaves);
		world.setBlock(i + 19, j + 1, k + 9, Blocks.leaves);
		world.setBlock(i + 19, j + 1, k + 10, Blocks.leaves);
		world.setBlock(i + 19, j + 1, k + 11, Blocks.leaves);
		world.setBlock(i + 19, j + 1, k + 12, Blocks.leaves);
		world.setBlock(i + 19, j + 2, k + 0, Blocks.leaves);
		world.setBlock(i + 19, j + 2, k + 1, Blocks.leaves);
		world.setBlock(i + 19, j + 2, k + 2, Blocks.leaves);
		world.setBlock(i + 19, j + 2, k + 3, Blocks.leaves);
		world.setBlock(i + 19, j + 2, k + 4, Blocks.leaves);
		world.setBlock(i + 19, j + 2, k + 5, Blocks.leaves);
		world.setBlock(i + 19, j + 2, k + 6, null, 0, k);
		world.setBlock(i + 19, j + 2, k + 7, Blocks.leaves);
		world.setBlock(i + 19, j + 2, k + 8, Blocks.leaves);
		world.setBlock(i + 19, j + 2, k + 9, Blocks.leaves);
		world.setBlock(i + 19, j + 2, k + 10, Blocks.leaves);
		world.setBlock(i + 19, j + 2, k + 11, Blocks.leaves);
		world.setBlock(i + 19, j + 2, k + 12, Blocks.leaves);
		world.setBlock(i + 19, j + 3, k + 0, null, 0, k);
		world.setBlock(i + 19, j + 3, k + 1, null, 0, k);
		world.setBlock(i + 19, j + 3, k + 2, null, 0, k);
		world.setBlock(i + 19, j + 3, k + 3, null, 0, k);
		world.setBlock(i + 19, j + 3, k + 4, null, 0, k);
		world.setBlock(i + 19, j + 3, k + 5, null, 0, k);
		world.setBlock(i + 19, j + 3, k + 6, Blocks.leaves);
		world.setBlock(i + 19, j + 3, k + 7, null, 0, k);
		world.setBlock(i + 19, j + 3, k + 8, null, 0, k);
		world.setBlock(i + 19, j + 3, k + 9, null, 0, k);
		world.setBlock(i + 19, j + 3, k + 10, null, 0, k);
		world.setBlock(i + 19, j + 3, k + 11, null, 0, k);
		world.setBlock(i + 19, j + 3, k + 12, null, 0, k);
		world.setBlock(i + 19, j + 4, k + 0, null, 0, k);
		world.setBlock(i + 19, j + 4, k + 1, null, 0, k);
		world.setBlock(i + 19, j + 4, k + 2, null, 0, k);
		world.setBlock(i + 19, j + 4, k + 3, null, 0, k);
		world.setBlock(i + 19, j + 4, k + 4, null, 0, k);
		world.setBlock(i + 19, j + 4, k + 5, null, 0, k);
		world.setBlock(i + 19, j + 4, k + 6, null, 0, k);
		world.setBlock(i + 19, j + 4, k + 7, null, 0, k);
		world.setBlock(i + 19, j + 4, k + 8, null, 0, k);
		world.setBlock(i + 19, j + 4, k + 9, null, 0, k);
		world.setBlock(i + 19, j + 4, k + 10, null, 0, k);
		world.setBlock(i + 19, j + 4, k + 11, null, 0, k);
		world.setBlock(i + 19, j + 4, k + 12, null, 0, k);
		world.setBlock(i + 4, j + 1, k + 4, Blocks.wheat);
		world.setBlock(i + 4, j + 1, k + 5, Blocks.wheat);
		world.setBlock(i + 4, j + 1, k + 6, Blocks.wheat);
		world.setBlock(i + 4, j + 1, k + 7, Blocks.wheat);
		world.setBlock(i + 4, j + 1, k + 8, Blocks.wheat);
		world.setBlock(i + 5, j + 0, k + 4, Blocks.water);
		world.setBlock(i + 5, j + 0, k + 5, Blocks.water);
		world.setBlock(i + 5, j + 0, k + 6, Blocks.water);
		world.setBlock(i + 5, j + 0, k + 7, Blocks.water);
		world.setBlock(i + 5, j + 0, k + 8, Blocks.water);
		world.setBlock(i + 6, j + 1, k + 4, Blocks.wheat);
		world.setBlock(i + 6, j + 1, k + 5, Blocks.wheat);
		world.setBlock(i + 6, j + 1, k + 6, Blocks.wheat);
		world.setBlock(i + 6, j + 1, k + 7, Blocks.wheat);
		world.setBlock(i + 6, j + 1, k + 8, Blocks.wheat);
		world.setBlock(i + 14, j + 2, k + 5, Blocks.wooden_pressure_plate);
		world.setBlock(i + 16, j + 1, k + 6, Blocks.wooden_door, 2, 0);
		world.setBlock(i + 16, j + 2, k + 6, Blocks.wooden_door, 8, 0);
		world.setBlock(i + 17, j + 3, k + 6, Blocks.torch);

		return true;
	}
}